Workbook
Name África_Sul_against: #REF!,#REF!,#REF!
Name África_Sul_played: #REF!,#REF!,#REF!
Name Alemanha_against: #REF!,#REF!,#REF!
Name Alemanha_played: #REF!,#REF!,#REF!
Name Arábia_Saudita_against: #REF!,#REF!,#REF!
Name Arábia_Saudita_played: #REF!,#REF!,#REF!
Name Argentina_against: #REF!,#REF!,#REF!
Name Argentina_played: #REF!,#REF!,#REF!
Name Bélgica_against: #REF!,#REF!,#REF!
Name Bélgica_played: #REF!,#REF!,#REF!
Name Brasil_against: #REF!,#REF!,#REF!
Name Brasil_played: #REF!,#REF!,#REF!
Name Camarões_against: #REF!,#REF!,#REF!
Name Camarões_played: #REF!,#REF!,#REF!
Name China_against: #REF!,#REF!,#REF!
Name China_played: #REF!,#REF!,#REF!
Name Coreia_against: #REF!,#REF!,#REF!
Name Coreia_played: #REF!,#REF!,#REF!
Name Costa_Rica_against: #REF!,#REF!,#REF!
Name Costa_Rica_played: #REF!,#REF!,#REF!
Name Croácia_against: #REF!,#REF!,#REF!
Name Croácia_played: #REF!,#REF!,#REF!
Name Dinamarca_against: #REF!,#REF!,#REF!
Name Dinamarca_played: #REF!,#REF!,#REF!
Name Equador_against: #REF!,#REF!,#REF!
Name Equador_played: #REF!,#REF!,#REF!
Name Eslovénia_against: #REF!,#REF!,#REF!
Name Eslovénia_played: #REF!,#REF!,#REF!
Name Espanha_against: #REF!,#REF!,#REF!
Name Espanha_played: #REF!,#REF!,#REF!
Name EUA_against: #REF!,#REF!,#REF!
Name EUA_played: #REF!,#REF!,#REF!
Name França_against: #REF!,#REF!,#REF!
Name França_played: #REF!,#REF!,#REF!
Name Inglaterra_against: #REF!,#REF!,#REF!
Name Inglaterra_played: #REF!,#REF!,#REF!
Name Irlanda_against: #REF!,#REF!,#REF!
Name Irlanda_played: #REF!,#REF!,#REF!
Name Itália_against: #REF!,#REF!,#REF!
Name Itália_played: #REF!,#REF!,#REF!
Name Japão_against: #REF!,#REF!,#REF!
Name Japão_played: #REF!,#REF!,#REF!
Name México_against: #REF!,#REF!,#REF!
Name México_played: #REF!,#REF!,#REF!
Name Nigéria_against: #REF!,#REF!,#REF!
Name Nigéria_played: #REF!,#REF!,#REF!
Name Paraguai_against: #REF!,#REF!,#REF!
Name Paraguai_played: #REF!,#REF!,#REF!
Name Polónia_against: #REF!,#REF!,#REF!
Name Polónia_played: #REF!,#REF!,#REF!
Name Portugal_against: #REF!,#REF!,#REF!
Name Portugal_played: #REF!,#REF!,#REF!
Name Rússia_against: #REF!,#REF!,#REF!
Name Rússia_played: #REF!,#REF!,#REF!
Name Senegal_against: #REF!,#REF!,#REF!
Name Senegal_played: #REF!,#REF!,#REF!
Name Suécia_against: #REF!,#REF!,#REF!
Name Suécia_played: #REF!,#REF!,#REF!
Name Tunísia_against: #REF!,#REF!,#REF!
Name Tunísia_played: #REF!,#REF!,#REF!

Sheet Jogos
B3: Grupo A | K3: Pontos ganhos | N3: Pontos Ganhos | Q3: Saldo de gols | U3: Saldo de gols
A4: Seleção | B4: PT | C4: J | D4: V | E4: E | F4: D | G4: GP | H4: GC | I4: SG | L4: PT | O4: pt | R4: PT | S4: SG | V4: PT | W4: SG | Y4: PT | Z4: SG | AC4: PT | AD4: SG | AE4: GP | AG4: PT | AH4: SG | AI4: GP | AK4: PT | AL4: SG | AM4: GP | AO4: PT | AP4: SG | AQ4: GP
A5: México | B5: =SUM((D5*3))+E5 -> 7 | C5: =COUNT('Tabela Jogos'!E4,'Tabela Jogos'!E7,'Tabela Jogos'!G9) -> 3 | D5: =SUM(IF(('Tabela Jogos'!$E$4>'Tabela Jogos'!$G$4),COUNT('Tabela Jogos'!$E$4)),IF(('Tabela Jogos'!$E$7>'Tabela Jogos'!$G$7),COUNT('Tabela Jogos'!$E$7)),IF(('Tabela Jogos'!$G$9>'Tabela Jogos'!$E$9),COUNT('Tabela Jogos'!$G$9))) -> 2 | E5: =SUM(IF(('Tabela Jogos'!$E$4='Tabela Jogos'!$G$4),COUNT('Tabela Jogos'!$E$4)),IF(('Tabela Jogos'!$E$7='Tabela Jogos'!$G$7),COUNT('Tabela Jogos'!$E$7)),IF(('Tabela Jogos'!$G$9='Tabela Jogos'!$E$9),COUNT('Tabela Jogos'!$G$9))) -> 1 | F5: =SUM(IF(('Tabela Jogos'!$E$4<'Tabela Jogos'!$G$4),COUNT('Tabela Jogos'!$E$4)),IF(('Tabela Jogos'!$E$7<'Tabela Jogos'!$G$7),COUNT('Tabela Jogos'!$E$7)),IF(('Tabela Jogos'!$G$9<'Tabela Jogos'!$E$9),COUNT('Tabela Jogos'!$G$9))) -> 0 | G5: =SUM((('Tabela Jogos'!E4+'Tabela Jogos'!E7)+'Tabela Jogos'!G9)) -> 5 | H5: =SUM((('Tabela Jogos'!G4+'Tabela Jogos'!G7)+'Tabela Jogos'!E9)) -> 2 | I5: =SUM((G5-H5)) -> 3 | K5: =IF(($B5>=$B6),$A5,$A6) -> México | L5: =VLOOKUP(K5,$A$5:$I$8,2,FALSE) -> 7 | N5: =IF((L5>=L7),K5,K7) -> México | O5: =VLOOKUP(N5,$A$5:$I$8,2,FALSE) -> 7 | Q5: =IF((O5>=O8),N5,N8) -> México | R5: =VLOOKUP(Q5,$A$5:$I$8,2,FALSE) -> 7 | S5: =VLOOKUP(Q5,$A$5:$I$8,9,FALSE) -> 3 | U5: =IF(AND((R5=R6),(S6>S5)),Q6,Q5) -> México | V5: =VLOOKUP(U5,$A$5:$I$8,2,FALSE) -> 7 | W5: =VLOOKUP(U5,$A$5:$I$8,9,FALSE) -> 3 | X5: =IF(AND((V5=V7),(W7>W5)),U7,U5) -> México | Y5: =VLOOKUP(X5,$A$5:$I$8,2,FALSE) -> 7 | Z5: =VLOOKUP(X5,$A$5:$I$8,9,FALSE) -> 3 | AB5: =IF(AND((Y5=Y8),(Z8>Z5)),X8,X5) -> México | AC5: =VLOOKUP(AB5,$A$5:$I$8,2,FALSE) -> 7 | AD5: =VLOOKUP(AB5,$A$5:$I$8,9,FALSE) -> 3 | AE5: =VLOOKUP(AB5,$A$5:$I$8,7,FALSE) -> 5 | AF5: =IF(AND((AC5=AC6),(AD5=AD6),(AE6>AE5)),AB6,AB5) -> México | AG5: =VLOOKUP(AF5,$A$5:$I$8,2,FALSE) -> 7 | AH5: =VLOOKUP(AF5,$A$5:$I$8,9,FALSE) -> 3 | AI5: =VLOOKUP(AF5,$A$5:$I$8,7,FALSE) -> 5 | AJ5: =IF(AND((AG5=AG7),(AH5=AH7),(AI7>AI5)),AF7,AF5) -> México | AK5: =VLOOKUP(AJ5,$A$5:$I$8,2,FALSE) -> 7 | AL5: =VLOOKUP(AJ5,$A$5:$I$8,9,FALSE) -> 3 | AM5: =VLOOKUP(AJ5,$A$5:$I$8,7,FALSE) -> 5 | AN5: =IF(AND((AK5=AK8),(AL5=AL8),(AM8>AM5)),AJ8,AJ5) -> México | AO5: =VLOOKUP(AN5,$A$5:$I$8,2,FALSE) -> 7 | AP5: =VLOOKUP(AN5,$A$5:$I$8,9,FALSE) -> 3 | AQ5: =VLOOKUP(AN5,$A$5:$I$8,7,FALSE) -> 5
A6: África do Sul | B6: =SUM((D6*3))+E6 -> 0 | C6: =COUNT('Tabela Jogos'!G4,'Tabela Jogos'!G6,'Tabela Jogos'!E8) -> 3 | D6: =SUM(IF(('Tabela Jogos'!$G$4>'Tabela Jogos'!$E$4),COUNT('Tabela Jogos'!$G$4)),IF(('Tabela Jogos'!$G$6>'Tabela Jogos'!$E$6),COUNT('Tabela Jogos'!$G$6)),IF(('Tabela Jogos'!$E$8>'Tabela Jogos'!$G$8),COUNT('Tabela Jogos'!$E$8))) -> 0 | E6: =SUM(IF(('Tabela Jogos'!$G$4='Tabela Jogos'!$E$4),COUNT('Tabela Jogos'!$G$4)),IF(('Tabela Jogos'!$G$6='Tabela Jogos'!$E$6),COUNT('Tabela Jogos'!$G$6)),IF(('Tabela Jogos'!$E$8='Tabela Jogos'!$G$8),COUNT('Tabela Jogos'!$E$8))) -> 0 | F6: =SUM(IF(('Tabela Jogos'!$G$4<'Tabela Jogos'!$E$4),COUNT('Tabela Jogos'!$G$4)),IF(('Tabela Jogos'!$G$6<'Tabela Jogos'!$E$6),COUNT('Tabela Jogos'!$G$6)),IF(('Tabela Jogos'!$E$8<'Tabela Jogos'!$G$8),COUNT('Tabela Jogos'!$E$8))) -> 3 | G6: =SUM((('Tabela Jogos'!G4+'Tabela Jogos'!G6)+'Tabela Jogos'!E8)) -> 2 | H6: =SUM((('Tabela Jogos'!E4+'Tabela Jogos'!E6)+'Tabela Jogos'!G8)) -> 5 | I6: =SUM((G6-H6)) -> -3 | K6: =IF((B6<=B5),A6,A5) -> África do Sul | L6: =VLOOKUP(K6,$A$5:$I$8,2,FALSE) -> 0 | N6: =IF((L6>=L8),K6,K8) -> Coréia do Sul | O6: =VLOOKUP(N6,$A$5:$I$8,2,FALSE) -> 4 | Q6: =IF((O6>=O7),N6,N7) -> República Tcheca | R6: =VLOOKUP(Q6,$A$5:$I$8,2,FALSE) -> 5 | S6: =VLOOKUP(Q6,$A$5:$I$8,9,FALSE) -> 1 | U6: =IF(AND((R5=R6),(S6>S5)),Q5,Q6) -> República Tcheca | V6: =VLOOKUP(U6,$A$5:$I$8,2,FALSE) -> 5 | W6: =VLOOKUP(U6,$A$5:$I$8,9,FALSE) -> 1 | X6: =IF(AND((V6=V8),(W8>W6)),U8,U6) -> República Tcheca | Y6: =VLOOKUP(X6,$A$5:$I$8,2,FALSE) -> 5 | Z6: =VLOOKUP(X6,$A$5:$I$8,9,FALSE) -> 1 | AB6: =IF(AND((Y6=Y7),(Z7>Z6)),X7,X6) -> República Tcheca | AC6: =VLOOKUP(AB6,$A$5:$I$8,2,FALSE) -> 5 | AD6: =VLOOKUP(AB6,$A$5:$I$8,9,FALSE) -> 1 | AE6: =VLOOKUP(AB6,$A$5:$I$8,7,FALSE) -> 4 | AF6: =IF(AND((AC6=AC5),(AD6=AD5),(AE6>AE5)),AB5,AB6) -> República Tcheca | AG6: =VLOOKUP(AF6,$A$5:$I$8,2,FALSE) -> 5 | AH6: =VLOOKUP(AF6,$A$5:$I$8,9,FALSE) -> 1 | AI6: =VLOOKUP(AF6,$A$5:$I$8,7,FALSE) -> 4 | AJ6: =IF(AND((AG6=AG8),(AH6=AH8),(AI8>AI6)),AF8,AF6) -> República Tcheca | AK6: =VLOOKUP(AJ6,$A$5:$I$8,2,FALSE) -> 5 | AL6: =VLOOKUP(AJ6,$A$5:$I$8,9,FALSE) -> 1 | AM6: =VLOOKUP(AJ6,$A$5:$I$8,7,FALSE) -> 4 | AN6: =IF(AND((AK6=AK7),(AL6=AL7),(AM7>AM6)),AJ7,AJ6) -> República Tcheca | AO6: =VLOOKUP(AN6,$A$5:$I$8,2,FALSE) -> 5 | AP6: =VLOOKUP(AN6,$A$5:$I$8,9,FALSE) -> 1 | AQ6: =VLOOKUP(AN6,$A$5:$I$8,7,FALSE) -> 4
A7: Coréia do Sul | B7: =SUM((D7*3))+E7 -> 4 | C7: =COUNT('Tabela Jogos'!E5,'Tabela Jogos'!G7,'Tabela Jogos'!G8) -> 3 | D7: =SUM(IF(('Tabela Jogos'!$E$5>'Tabela Jogos'!$G$5),COUNT('Tabela Jogos'!$E$5)),IF(('Tabela Jogos'!$G$7>'Tabela Jogos'!$E$7),COUNT('Tabela Jogos'!$G$7)),IF(('Tabela Jogos'!$G$8>'Tabela Jogos'!$E$8),COUNT('Tabela Jogos'!$G$8))) -> 1 | E7: =SUM(IF(('Tabela Jogos'!$E$5='Tabela Jogos'!$G$5),COUNT('Tabela Jogos'!$E$5)),IF(('Tabela Jogos'!$G$7='Tabela Jogos'!$E$7),COUNT('Tabela Jogos'!$G$7)),IF(('Tabela Jogos'!$G$8='Tabela Jogos'!$E$8),COUNT('Tabela Jogos'!$G$8))) -> 1 | F7: =SUM(IF(('Tabela Jogos'!$E$5<'Tabela Jogos'!$G$5),COUNT('Tabela Jogos'!$E$5)),IF(('Tabela Jogos'!$G$7<'Tabela Jogos'!$E$7),COUNT('Tabela Jogos'!$G$7)),IF(('Tabela Jogos'!$G$8<'Tabela Jogos'!$E$8),COUNT('Tabela Jogos'!$G$8))) -> 1 | G7: =SUM((('Tabela Jogos'!E5+'Tabela Jogos'!G7)+'Tabela Jogos'!G8)) -> 2 | H7: =SUM((('Tabela Jogos'!G5+'Tabela Jogos'!E7)+'Tabela Jogos'!E8)) -> 3 | I7: =SUM((G7-H7)) -> -1 | K7: =IF((B7>=B8),A7,A8) -> República Tcheca | L7: =VLOOKUP(K7,$A$5:$I$8,2,FALSE) -> 5 | N7: =IF((L7<=L5),K7,K5) -> República Tcheca | O7: =VLOOKUP(N7,$A$5:$I$8,2,FALSE) -> 5 | Q7: =IF((O7<=O6),N7,N6) -> Coréia do Sul | R7: =VLOOKUP(Q7,$A$5:$I$8,2,FALSE) -> 4 | S7: =VLOOKUP(Q7,$A$5:$I$8,9,FALSE) -> -1 | U7: =IF(AND((R7=R8),(S8>S7)),Q8,Q7) -> Coréia do Sul | V7: =VLOOKUP(U7,$A$5:$I$8,2,FALSE) -> 4 | W7: =VLOOKUP(U7,$A$5:$I$8,9,FALSE) -> -1 | X7: =IF(AND((V5=V7),(W7>W5)),U5,U7) -> Coréia do Sul | Y7: =VLOOKUP(X7,$A$5:$I$8,2,FALSE) -> 4 | Z7: =VLOOKUP(X7,$A$5:$I$8,9,FALSE) -> -1 | AB7: =IF(AND((Y7=Y6),(Z7>Z6)),X6,X7) -> Coréia do Sul | AC7: =VLOOKUP(AB7,$A$5:$I$8,2,FALSE) -> 4 | AD7: =VLOOKUP(AB7,$A$5:$I$8,9,FALSE) -> -1 | AE7: =VLOOKUP(AB7,$A$5:$I$8,7,FALSE) -> 2 | AF7: =IF(AND((AC7=AC8),(AD7=AD8),(AE8>AE7)),AB8,AB7) -> Coréia do Sul | AG7: =VLOOKUP(AF7,$A$5:$I$8,2,FALSE) -> 4 | AH7: =VLOOKUP(AF7,$A$5:$I$8,9,FALSE) -> -1 | AI7: =VLOOKUP(AF7,$A$5:$I$8,7,FALSE) -> 2 | AJ7: =IF(AND((AG7=AG5),(AH7=AH5),(AI7>AI5)),AF5,AF7) -> Coréia do Sul | AK7: =VLOOKUP(AJ7,$A$5:$I$8,2,FALSE) -> 4 | AL7: =VLOOKUP(AJ7,$A$5:$I$8,9,FALSE) -> -1 | AM7: =VLOOKUP(AJ7,$A$5:$I$8,7,FALSE) -> 2 | AN7: =IF(AND((AK7=AK6),(AL7=AL6),(AM7>AM6)),AJ6,AJ7) -> Coréia do Sul | AO7: =VLOOKUP(AN7,$A$5:$I$8,2,FALSE) -> 4 | AP7: =VLOOKUP(AN7,$A$5:$I$8,9,FALSE) -> -1 | AQ7: =VLOOKUP(AN7,$A$5:$I$8,7,FALSE) -> 2
A8: República Tcheca | B8: =SUM((D8*3))+E8 -> 5 | C8: =COUNT('Tabela Jogos'!G5,'Tabela Jogos'!E6,'Tabela Jogos'!E9) -> 3 | D8: =SUM(IF(('Tabela Jogos'!$G$5>'Tabela Jogos'!$E$5),COUNT('Tabela Jogos'!$G$5)),IF(('Tabela Jogos'!$E$6>'Tabela Jogos'!$G$6),COUNT('Tabela Jogos'!$E$6)),IF(('Tabela Jogos'!$E$9>'Tabela Jogos'!$G$9),COUNT('Tabela Jogos'!$E$9))) -> 1 | E8: =SUM(IF(('Tabela Jogos'!$G$5='Tabela Jogos'!$E$5),COUNT('Tabela Jogos'!$G$5)),IF(('Tabela Jogos'!$E$6='Tabela Jogos'!$G$6),COUNT('Tabela Jogos'!$E$6)),IF(('Tabela Jogos'!$E$9='Tabela Jogos'!$G$9),COUNT('Tabela Jogos'!$E$9))) -> 2 | F8: =SUM(IF(('Tabela Jogos'!$G$5<'Tabela Jogos'!$E$5),COUNT('Tabela Jogos'!$G$5)),IF(('Tabela Jogos'!$E$6<'Tabela Jogos'!$G$6),COUNT('Tabela Jogos'!$E$6)),IF(('Tabela Jogos'!$E$9<'Tabela Jogos'!$G$9),COUNT('Tabela Jogos'!$E$9))) -> 0 | G8: =SUM((('Tabela Jogos'!G5+'Tabela Jogos'!E6)+'Tabela Jogos'!E9)) -> 4 | H8: =SUM((('Tabela Jogos'!E5+'Tabela Jogos'!G6)+'Tabela Jogos'!G9)) -> 3 | I8: =SUM((G8-H8)) -> 1 | K8: =IF((B8<=B7),A8,A7) -> Coréia do Sul | L8: =VLOOKUP(K8,$A$5:$I$8,2,FALSE) -> 4 | N8: =IF((L8<=L6),K8,K6) -> África do Sul | O8: =VLOOKUP(N8,$A$5:$I$8,2,FALSE) -> 0 | Q8: =IF((O8<=O5),N8,N5) -> África do Sul | R8: =VLOOKUP(Q8,$A$5:$I$8,2,FALSE) -> 0 | S8: =VLOOKUP(Q8,$A$5:$I$8,9,FALSE) -> -3 | U8: =IF(AND((R7=R8),(S8>S7)),Q7,Q8) -> África do Sul | V8: =VLOOKUP(U8,$A$5:$I$8,2,FALSE) -> 0 | W8: =VLOOKUP(U8,$A$5:$I$8,9,FALSE) -> -3 | X8: =IF(AND((V6=V8),(W8>W6)),U6,U8) -> África do Sul | Y8: =VLOOKUP(X8,$A$5:$I$8,2,FALSE) -> 0 | Z8: =VLOOKUP(X8,$A$5:$I$8,9,FALSE) -> -3 | AB8: =IF(AND((Y8=Y5),(Z8>Z5)),X5,X8) -> África do Sul | AC8: =VLOOKUP(AB8,$A$5:$I$8,2,FALSE) -> 0 | AD8: =VLOOKUP(AB8,$A$5:$I$8,9,FALSE) -> -3 | AE8: =VLOOKUP(AB8,$A$5:$I$8,7,FALSE) -> 2 | AF8: =IF(AND((AC8=AC7),(AD8=AD7),(AE8>AE7)),X7,X8) -> África do Sul | AG8: =VLOOKUP(AF8,$A$5:$I$8,2,FALSE) -> 0 | AH8: =VLOOKUP(AF8,$A$5:$I$8,9,FALSE) -> -3 | AI8: =VLOOKUP(AF8,$A$5:$I$8,7,FALSE) -> 2 | AJ8: =IF(AND((AG6=AG8),(AH6=AH8),(AI8>AI6)),AF6,AF8) -> África do Sul | AK8: =VLOOKUP(AJ8,$A$5:$I$8,2,FALSE) -> 0 | AL8: =VLOOKUP(AJ8,$A$5:$I$8,9,FALSE) -> -3 | AM8: =VLOOKUP(AJ8,$A$5:$I$8,7,FALSE) -> 2 | AN8: =IF(AND((AK8=AK5),(AL8=AL5),(AM8>AM5)),AJ5,AJ8) -> África do Sul | AO8: =VLOOKUP(AN8,$A$5:$I$8,2,FALSE) -> 0 | AP8: =VLOOKUP(AN8,$A$5:$I$8,9,FALSE) -> -3 | AQ8: =VLOOKUP(AN8,$A$5:$I$8,7,FALSE) -> 2
B11: Grupo B | K11: Pontos ganhos | N11: Pontos Ganhos | Q11: Saldo de gols | U11: Saldo de gols
A12: Seleção | B12: PT | C12: J | D12: V | E12: E | F12: D | G12: GP | H12: GC | I12: SG | L12: PT | O12: pt | R12: PT | S12: SG | V12: PT | W12: SG | Y12: PT | Z12: SG | AC12: PT | AD12: SG | AE12: GP | AG12: PT | AH12: SG | AI12: GP | AK12: PT | AL12: SG | AM12: GP | AO12: PT | AP12: SG | AQ12: GP
A13: Canadá | B13: =SUM((D13*3))+E13 -> 6 | C13: =COUNT('Tabela Jogos'!E12,'Tabela Jogos'!E15,'Tabela Jogos'!G16) -> 3 | D13: =SUM(IF(('Tabela Jogos'!$E$12>'Tabela Jogos'!$G$12),COUNT('Tabela Jogos'!$E$12)),IF(('Tabela Jogos'!$E$15>'Tabela Jogos'!$G$15),COUNT('Tabela Jogos'!$E$15)),IF(('Tabela Jogos'!$G$16>'Tabela Jogos'!$E$16),COUNT('Tabela Jogos'!$G$16))) -> 2 | E13: =SUM(IF(('Tabela Jogos'!$E$12='Tabela Jogos'!$G$12),COUNT('Tabela Jogos'!$E$12)),IF(('Tabela Jogos'!$E$15='Tabela Jogos'!$G$15),COUNT('Tabela Jogos'!$E$15)),IF(('Tabela Jogos'!$G$16='Tabela Jogos'!$E$16),COUNT('Tabela Jogos'!$G$16))) -> 0 | F13: =SUM(IF(('Tabela Jogos'!$E$12<'Tabela Jogos'!$G$12),COUNT('Tabela Jogos'!$E$12)),IF(('Tabela Jogos'!$E$15<'Tabela Jogos'!$G$15),COUNT('Tabela Jogos'!$E$15)),IF(('Tabela Jogos'!$G$16<'Tabela Jogos'!$E$16),COUNT('Tabela Jogos'!$G$16))) -> 1 | G13: =SUM((('Tabela Jogos'!E12+'Tabela Jogos'!E15)+'Tabela Jogos'!G16)) -> 5 | H13: =SUM((('Tabela Jogos'!G12+'Tabela Jogos'!G15)+'Tabela Jogos'!E16)) -> 2 | I13: =SUM((G13-H13)) -> 3 | K13: =IF((B13>=B14),A13,A14) -> Canadá | L13: =VLOOKUP(K13,$A$13:$I$16,2,FALSE) -> 6 | N13: =IF((L13>=L15),K13,K15) -> Suíça | O13: =VLOOKUP(N13,$A$13:$I$16,2,FALSE) -> 9 | Q13: =IF((O13>=O16),N13,N16) -> Suíça | R13: =VLOOKUP(Q13,$A$13:$I$16,2,FALSE) -> 9 | S13: =VLOOKUP(Q13,$A$13:$I$16,9,FALSE) -> 4 | U13: =IF(AND((R13=R14),(S14>S13)),Q14,Q13) -> Suíça | V13: =VLOOKUP(U13,$A$13:$I$16,2,FALSE) -> 9 | W13: =VLOOKUP(U13,$A$13:$I$16,9,FALSE) -> 4 | X13: =IF(AND((V13=V15),(W15>W13)),U15,U13) -> Suíça | Y13: =VLOOKUP(X13,$A$13:$I$16,2,FALSE) -> 9 | Z13: =VLOOKUP(X13,$A$13:$I$16,9,FALSE) -> 4 | AB13: =IF(AND((Y13=Y16),(Z16>Z13)),X16,X13) -> Suíça | AC13: =VLOOKUP(AB13,$A$13:$I$16,2,FALSE) -> 9 | AD13: =VLOOKUP(AB13,$A$13:$I$16,9,FALSE) -> 4 | AE13: =VLOOKUP(AB13,$A$13:$I$16,7,FALSE) -> 4 | AF13: =IF(AND((AC13=AC14),(AD13=AD14),(AE14>AE13)),AB14,AB13) -> Suíça | AG13: =VLOOKUP(AF13,$A$13:$I$16,2,FALSE) -> 9 | AH13: =VLOOKUP(AF13,$A$13:$I$16,9,FALSE) -> 4 | AI13: =VLOOKUP(AF13,$A$13:$I$16,7,FALSE) -> 4 | AJ13: =IF(AND((AG13=AG15),(AH13=AH15),(AI15>AI13)),AF15,AF13) -> Suíça | AK13: =VLOOKUP(AJ13,$A$13:$I$16,2,FALSE) -> 9 | AL13: =VLOOKUP(AJ13,$A$13:$I$16,9,FALSE) -> 4 | AM13: =VLOOKUP(AJ13,$A$13:$I$16,7,FALSE) -> 4 | AN13: =IF(AND((AK13=AK16),(AL13=AL16),(AM16>AM13)),AJ16,AJ13) -> Suíça | AO13: =VLOOKUP(AN13,$A$13:$I$16,2,FALSE) -> 9 | AP13: =VLOOKUP(AN13,$A$13:$I$16,9,FALSE) -> 4 | AQ13: =VLOOKUP(AN13,$A$13:$I$16,7,FALSE) -> 4
A14: Bósnia | B14: =SUM((D14*3))+E14 -> 3 | C14: =COUNT('Tabela Jogos'!G12,'Tabela Jogos'!G14,'Tabela Jogos'!E17) -> 3 | D14: =SUM(IF(('Tabela Jogos'!$G$12>'Tabela Jogos'!$E$12),COUNT('Tabela Jogos'!$G$12)),IF(('Tabela Jogos'!$G$14>'Tabela Jogos'!$E$14),COUNT('Tabela Jogos'!$G$14)),IF(('Tabela Jogos'!$E$17>'Tabela Jogos'!$G$17),COUNT('Tabela Jogos'!$E$17))) -> 1 | E14: =SUM(IF(('Tabela Jogos'!$G$12='Tabela Jogos'!$E$12),COUNT('Tabela Jogos'!$G$12)),IF(('Tabela Jogos'!$G$14='Tabela Jogos'!$E$14),COUNT('Tabela Jogos'!$G$14)),IF(('Tabela Jogos'!$E$17='Tabela Jogos'!$G$17),COUNT('Tabela Jogos'!$E$17))) -> 0 | F14: =SUM(IF(('Tabela Jogos'!$G$12<'Tabela Jogos'!$E$12),COUNT('Tabela Jogos'!$G$12)),IF(('Tabela Jogos'!$G$14<'Tabela Jogos'!$E$14),COUNT('Tabela Jogos'!$G$14)),IF(('Tabela Jogos'!$E$17<'Tabela Jogos'!$G$17),COUNT('Tabela Jogos'!$E$17))) -> 2 | G14: =SUM((('Tabela Jogos'!G12+'Tabela Jogos'!G14)+'Tabela Jogos'!E17)) -> 3 | H14: =SUM((('Tabela Jogos'!E12+'Tabela Jogos'!E14)+'Tabela Jogos'!G17)) -> 4 | I14: =SUM((G14-H14)) -> -1 | K14: =IF((B14<=B13),A14,A13) -> Bósnia | L14: =VLOOKUP(K14,$A$13:$I$16,2,FALSE) -> 3 | N14: =IF((L14>=L16),K14,K16) -> Bósnia | O14: =VLOOKUP(N14,$A$13:$I$16,2,FALSE) -> 3 | Q14: =IF((O14>=O15),N14,N15) -> Canadá | R14: =VLOOKUP(Q14,$A$13:$I$16,2,FALSE) -> 6 | S14: =VLOOKUP(Q14,$A$13:$I$16,9,FALSE) -> 3 | U14: =IF(AND((R13=R14),(S14>S13)),Q13,Q14) -> Canadá | V14: =VLOOKUP(U14,$A$13:$I$16,2,FALSE) -> 6 | W14: =VLOOKUP(U14,$A$13:$I$16,9,FALSE) -> 3 | X14: =IF(AND((V14=V16),(W16>W14)),U16,U14) -> Canadá | Y14: =VLOOKUP(X14,$A$13:$I$16,2,FALSE) -> 6 | Z14: =VLOOKUP(X14,$A$13:$I$16,9,FALSE) -> 3 | AB14: =IF(AND((Y14=Y15),(Z15>Z14)),X15,X14) -> Canadá | AC14: =VLOOKUP(AB14,$A$13:$I$16,2,FALSE) -> 6 | AD14: =VLOOKUP(AB14,$A$13:$I$16,9,FALSE) -> 3 | AE14: =VLOOKUP(AB14,$A$13:$I$16,7,FALSE) -> 5 | AF14: =IF(AND((AC14=AC13),(AD14=AD13),(AE14>AE13)),AB13,AB14) -> Canadá | AG14: =VLOOKUP(AF14,$A$13:$I$16,2,FALSE) -> 6 | AH14: =VLOOKUP(AF14,$A$13:$I$16,9,FALSE) -> 3 | AI14: =VLOOKUP(AF14,$A$13:$I$16,7,FALSE) -> 5 | AJ14: =IF(AND((AG14=AG16),(AH14=AH16),(AI16>AI14)),AF16,AF14) -> Canadá | AK14: =VLOOKUP(AJ14,$A$13:$I$16,2,FALSE) -> 6 | AL14: =VLOOKUP(AJ14,$A$13:$I$16,9,FALSE) -> 3 | AM14: =VLOOKUP(AJ14,$A$13:$I$16,7,FALSE) -> 5 | AN14: =IF(AND((AK14=AK15),(AL14=AL15),(AM15>AM14)),AJ15,AJ14) -> Canadá | AO14: =VLOOKUP(AN14,$A$13:$I$16,2,FALSE) -> 6 | AP14: =VLOOKUP(AN14,$A$13:$I$16,9,FALSE) -> 3 | AQ14: =VLOOKUP(AN14,$A$13:$I$16,7,FALSE) -> 5
A15: Catar | B15: =SUM((D15*3))+E15 -> 0 | C15: =COUNT('Tabela Jogos'!E13,'Tabela Jogos'!G15,'Tabela Jogos'!G17) -> 3 | D15: =SUM(IF(('Tabela Jogos'!$E$13>'Tabela Jogos'!$G$13),COUNT('Tabela Jogos'!$E$13)),IF(('Tabela Jogos'!$G$15>'Tabela Jogos'!$E$15),COUNT('Tabela Jogos'!$G$15)),IF(('Tabela Jogos'!$G$17>'Tabela Jogos'!$E$17),COUNT('Tabela Jogos'!$G$17))) -> 0 | E15: =SUM(IF(('Tabela Jogos'!$E$13='Tabela Jogos'!$G$13),COUNT('Tabela Jogos'!$E$13)),IF(('Tabela Jogos'!$G$15='Tabela Jogos'!$E$15),COUNT('Tabela Jogos'!$G$15)),IF(('Tabela Jogos'!$G$17='Tabela Jogos'!$E$17),COUNT('Tabela Jogos'!$G$17))) -> 0 | F15: =SUM(IF(('Tabela Jogos'!$E$13<'Tabela Jogos'!$G$13),COUNT('Tabela Jogos'!$E$13)),IF(('Tabela Jogos'!$G$15<'Tabela Jogos'!$E$15),COUNT('Tabela Jogos'!$G$15)),IF(('Tabela Jogos'!$G$17<'Tabela Jogos'!$E$17),COUNT('Tabela Jogos'!$G$17))) -> 3 | G15: =SUM((('Tabela Jogos'!E13+'Tabela Jogos'!G15)+'Tabela Jogos'!G17)) -> 1 | H15: =SUM((('Tabela Jogos'!G13+'Tabela Jogos'!E15)+'Tabela Jogos'!E17)) -> 7 | I15: =SUM((G15-H15)) -> -6 | K15: =IF((B15>=B16),A15,A16) -> Suíça | L15: =VLOOKUP(K15,$A$13:$I$16,2,FALSE) -> 9 | N15: =IF((L15<=L13),K15,K13) -> Canadá | O15: =VLOOKUP(N15,$A$13:$I$16,2,FALSE) -> 6 | Q15: =IF((O15<=O14),N15,N14) -> Bósnia | R15: =VLOOKUP(Q15,$A$13:$I$16,2,FALSE) -> 3 | S15: =VLOOKUP(Q15,$A$13:$I$16,9,FALSE) -> -1 | U15: =IF(AND((R15=R16),(S16>S15)),Q16,Q15) -> Bósnia | V15: =VLOOKUP(U15,$A$13:$I$16,2,FALSE) -> 3 | W15: =VLOOKUP(U15,$A$13:$I$16,9,FALSE) -> -1 | X15: =IF(AND((V13=V15),(W15>W13)),U13,U15) -> Bósnia | Y15: =VLOOKUP(X15,$A$13:$I$16,2,FALSE) -> 3 | Z15: =VLOOKUP(X15,$A$13:$I$16,9,FALSE) -> -1 | AB15: =IF(AND((Y15=Y14),(Z15>Z14)),X14,X15) -> Bósnia | AC15: =VLOOKUP(AB15,$A$13:$I$16,2,FALSE) -> 3 | AD15: =VLOOKUP(AB15,$A$13:$I$16,9,FALSE) -> -1 | AE15: =VLOOKUP(AB15,$A$13:$I$16,7,FALSE) -> 3 | AF15: =IF(AND((AC15=AC16),(AD15=AD16),(AE16>AE15)),AB16,AB15) -> Bósnia | AG15: =VLOOKUP(AF15,$A$13:$I$16,2,FALSE) -> 3 | AH15: =VLOOKUP(AF15,$A$13:$I$16,9,FALSE) -> -1 | AI15: =VLOOKUP(AF15,$A$13:$I$16,7,FALSE) -> 3 | AJ15: =IF(AND((AG15=AG13),(AH15=AH13),(AI15>AI13)),AF13,AF15) -> Bósnia | AK15: =VLOOKUP(AJ15,$A$13:$I$16,2,FALSE) -> 3 | AL15: =VLOOKUP(AJ15,$A$13:$I$16,9,FALSE) -> -1 | AM15: =VLOOKUP(AJ15,$A$13:$I$16,7,FALSE) -> 3 | AN15: =IF(AND((AK15=AK14),(AL15=AL14),(AM15>AM14)),AJ14,AJ15) -> Bósnia | AO15: =VLOOKUP(AN15,$A$13:$I$16,2,FALSE) -> 3 | AP15: =VLOOKUP(AN15,$A$13:$I$16,9,FALSE) -> -1 | AQ15: =VLOOKUP(AN15,$A$13:$I$16,7,FALSE) -> 3
A16: Suíça | B16: =SUM((D16*3))+E16 -> 9 | C16: =COUNT('Tabela Jogos'!G13,'Tabela Jogos'!E14,'Tabela Jogos'!E16) -> 3 | D16: =SUM(IF(('Tabela Jogos'!$G$13>'Tabela Jogos'!$E$13),COUNT('Tabela Jogos'!$G$13)),IF(('Tabela Jogos'!$E$14>'Tabela Jogos'!$G$14),COUNT('Tabela Jogos'!$E$14)),IF(('Tabela Jogos'!$E$16>'Tabela Jogos'!$G$16),COUNT('Tabela Jogos'!$E$16))) -> 3 | E16: =SUM(IF(('Tabela Jogos'!$G$13='Tabela Jogos'!$E$13),COUNT('Tabela Jogos'!$G$13)),IF(('Tabela Jogos'!$E$14='Tabela Jogos'!$G$14),COUNT('Tabela Jogos'!$E$14)),IF(('Tabela Jogos'!$E$16='Tabela Jogos'!$G$16),COUNT('Tabela Jogos'!$E$16))) -> 0 | F16: =SUM(IF(('Tabela Jogos'!$G$13<'Tabela Jogos'!$E$13),COUNT('Tabela Jogos'!$G$13)),IF(('Tabela Jogos'!$E$14<'Tabela Jogos'!$G$14),COUNT('Tabela Jogos'!$E$14)),IF(('Tabela Jogos'!$E$16<'Tabela Jogos'!$G$16),COUNT('Tabela Jogos'!$E$16))) -> 0 | G16: =SUM((('Tabela Jogos'!G13+'Tabela Jogos'!E14)+'Tabela Jogos'!E16)) -> 4 | H16: =SUM((('Tabela Jogos'!E13+'Tabela Jogos'!G14)+'Tabela Jogos'!G16)) -> 0 | I16: =SUM((G16-H16)) -> 4 | K16: =IF((B16<=B15),A16,A15) -> Catar | L16: =VLOOKUP(K16,$A$13:$I$16,2,FALSE) -> 0 | N16: =IF((L16<=L14),K16,K14) -> Catar | O16: =VLOOKUP(N16,$A$13:$I$16,2,FALSE) -> 0 | Q16: =IF((O16<=O13),N16,N13) -> Catar | R16: =VLOOKUP(Q16,$A$13:$I$16,2,FALSE) -> 0 | S16: =VLOOKUP(Q16,$A$13:$I$16,9,FALSE) -> -6 | U16: =IF(AND((R15=R16),(S16>S15)),Q15,Q16) -> Catar | V16: =VLOOKUP(U16,$A$13:$I$16,2,FALSE) -> 0 | W16: =VLOOKUP(U16,$A$13:$I$16,9,FALSE) -> -6 | X16: =IF(AND((V14=V16),(W16>W14)),U14,U16) -> Catar | Y16: =VLOOKUP(X16,$A$13:$I$16,2,FALSE) -> 0 | Z16: =VLOOKUP(X16,$A$13:$I$16,9,FALSE) -> -6 | AB16: =IF(AND((Y16=Y13),(Z16>Z13)),X13,X16) -> Catar | AC16: =VLOOKUP(AB16,$A$13:$I$16,2,FALSE) -> 0 | AD16: =VLOOKUP(AB16,$A$13:$I$16,9,FALSE) -> -6 | AE16: =VLOOKUP(AB16,$A$13:$I$16,7,FALSE) -> 1 | AF16: =IF(AND((AC16=AC15),(AD16=AD15),(AE16>AE15)),X15,X16) -> Catar | AG16: =VLOOKUP(AF16,$A$13:$I$16,2,FALSE) -> 0 | AH16: =VLOOKUP(AF16,$A$13:$I$16,9,FALSE) -> -6 | AI16: =VLOOKUP(AF16,$A$13:$I$16,7,FALSE) -> 1 | AJ16: =IF(AND((AG14=AG16),(AH14=AH16),(AI16>AI14)),AF14,AF16) -> Catar | AK16: =VLOOKUP(AJ16,$A$13:$I$16,2,FALSE) -> 0 | AL16: =VLOOKUP(AJ16,$A$13:$I$16,9,FALSE) -> -6 | AM16: =VLOOKUP(AJ16,$A$13:$I$16,7,FALSE) -> 1 | AN16: =IF(AND((AK16=AK13),(AL16=AL13),(AM16>AM13)),AJ13,AJ16) -> Catar | AO16: =VLOOKUP(AN16,$A$13:$I$16,2,FALSE) -> 0 | AP16: =VLOOKUP(AN16,$A$13:$I$16,9,FALSE) -> -6 | AQ16: =VLOOKUP(AN16,$A$13:$I$16,7,FALSE) -> 1
B19: Grupo C | K19: Pontos ganhos | N19: Pontos Ganhos | Q19: Saldo de gols | U19: Saldo de gols
A20: Seleção | B20: PT | C20: J | D20: V | E20: E | F20: D | G20: GP | H20: GC | I20: SG | L20: PT | O20: pt | R20: PT | S20: SG | V20: PT | W20: SG | Y20: PT | Z20: SG | AC20: PT | AD20: SG | AE20: GP | AG20: PT | AH20: SG | AI20: GP | AK20: PT | AL20: SG | AM20: GP | AO20: PT | AP20: SG | AQ20: GP
A21: Brasil | B21: =SUM((D21*3))+E21 -> 7 | C21: =COUNT('Tabela Jogos'!E20,'Tabela Jogos'!E23,'Tabela Jogos'!G25) -> 3 | D21: =SUM(IF(('Tabela Jogos'!$E$20>'Tabela Jogos'!$G$20),COUNT('Tabela Jogos'!$E$20)),IF(('Tabela Jogos'!$E$23>'Tabela Jogos'!$G$23),COUNT('Tabela Jogos'!$E$23)),IF(('Tabela Jogos'!$G$25>'Tabela Jogos'!$E$25),COUNT('Tabela Jogos'!$G$25))) -> 2 | E21: =SUM(IF(('Tabela Jogos'!$E$20='Tabela Jogos'!$G$20),COUNT('Tabela Jogos'!$E$20)),IF(('Tabela Jogos'!$E$23='Tabela Jogos'!$G$23),COUNT('Tabela Jogos'!$E$23)),IF(('Tabela Jogos'!$G$25='Tabela Jogos'!$E$25),COUNT('Tabela Jogos'!$G$25))) -> 1 | F21: =SUM(IF(('Tabela Jogos'!$E$20<'Tabela Jogos'!$G$20),COUNT('Tabela Jogos'!$E$20)),IF(('Tabela Jogos'!$E$23<'Tabela Jogos'!$G$23),COUNT('Tabela Jogos'!$E$23)),IF(('Tabela Jogos'!$G$25<'Tabela Jogos'!$E$25),COUNT('Tabela Jogos'!$G$25))) -> 0 | G21: =SUM((('Tabela Jogos'!E20+'Tabela Jogos'!E23)+'Tabela Jogos'!G25)) -> 7 | H21: =SUM((('Tabela Jogos'!G20+'Tabela Jogos'!G23)+'Tabela Jogos'!E25)) -> 1 | I21: =SUM((G21-H21)) -> 6 | K21: =IF((B21>=B22),A21,A22) -> Brasil | L21: =VLOOKUP(K21,$A$21:$I$24,2,FALSE) -> 7 | N21: =IF((L21>=L23),K21,K23) -> Brasil | O21: =VLOOKUP(N21,$A$21:$I$24,2,FALSE) -> 7 | Q21: =IF((O21>=O24),N21,N24) -> Brasil | R21: =VLOOKUP(Q21,$A$21:$I$24,2,FALSE) -> 7 | S21: =VLOOKUP(Q21,$A$21:$I$24,9,FALSE) -> 6 | U21: =IF(AND((R21=R22),(S22>S21)),Q22,Q21) -> Brasil | V21: =VLOOKUP(U21,$A$21:$I$24,2,FALSE) -> 7 | W21: =VLOOKUP(U21,$A$21:$I$24,9,FALSE) -> 6 | X21: =IF(AND((V21=V23),(W23>W21)),U23,U21) -> Brasil | Y21: =VLOOKUP(X21,$A$21:$I$24,2,FALSE) -> 7 | Z21: =VLOOKUP(X21,$A$21:$I$24,9,FALSE) -> 6 | AB21: =IF(AND((Y21=Y24),(Z24>Z21)),X24,X21) -> Brasil | AC21: =VLOOKUP(AB21,$A$21:$I$24,2,FALSE) -> 7 | AD21: =VLOOKUP(AB21,$A$21:$I$24,9,FALSE) -> 6 | AE21: =VLOOKUP(AB21,$A$21:$I$24,7,FALSE) -> 7 | AF21: =IF(AND((AC21=AC22),(AD21=AD22),(AE22>AE21)),AB22,AB21) -> Brasil | AG21: =VLOOKUP(AF21,$A$21:$I$24,2,FALSE) -> 7 | AH21: =VLOOKUP(AF21,$A$21:$I$24,9,FALSE) -> 6 | AI21: =VLOOKUP(AF21,$A$21:$I$24,7,FALSE) -> 7 | AJ21: =IF(AND((AG21=AG23),(AH21=AH23),(AI23>AI21)),AF23,AF21) -> Brasil | AK21: =VLOOKUP(AJ21,$A$21:$I$24,2,FALSE) -> 7 | AL21: =VLOOKUP(AJ21,$A$21:$I$24,9,FALSE) -> 6 | AM21: =VLOOKUP(AJ21,$A$21:$I$24,7,FALSE) -> 7 | AN21: =IF(AND((AK21=AK24),(AL21=AL24),(AM24>AM21)),AJ24,AJ21) -> Brasil | AO21: =VLOOKUP(AN21,$A$21:$I$24,2,FALSE) -> 7 | AP21: =VLOOKUP(AN21,$A$21:$I$24,9,FALSE) -> 6 | AQ21: =VLOOKUP(AN21,$A$21:$I$24,7,FALSE) -> 7
A22: Marrocos | B22: =SUM((D22*3))+E22 -> 7 | C22: =COUNT('Tabela Jogos'!G20,'Tabela Jogos'!G22,'Tabela Jogos'!E24) -> 3 | D22: =SUM(IF(('Tabela Jogos'!$G$20>'Tabela Jogos'!$E$20),COUNT('Tabela Jogos'!$G$20)),IF(('Tabela Jogos'!$G$22>'Tabela Jogos'!$E$22),COUNT('Tabela Jogos'!$G$22)),IF(('Tabela Jogos'!$E$24>'Tabela Jogos'!$G$24),COUNT('Tabela Jogos'!$E$24))) -> 2 | E22: =SUM(IF(('Tabela Jogos'!$G$20='Tabela Jogos'!$E$20),COUNT('Tabela Jogos'!$G$20)),IF(('Tabela Jogos'!$G$22='Tabela Jogos'!$E$22),COUNT('Tabela Jogos'!$G$22)),IF(('Tabela Jogos'!$E$24='Tabela Jogos'!$G$24),COUNT('Tabela Jogos'!$E$24))) -> 1 | F22: =SUM(IF(('Tabela Jogos'!$G$20<'Tabela Jogos'!$E$20),COUNT('Tabela Jogos'!$G$20)),IF(('Tabela Jogos'!$G$22<'Tabela Jogos'!$E$22),COUNT('Tabela Jogos'!$G$22)),IF(('Tabela Jogos'!$E$24<'Tabela Jogos'!$G$24),COUNT('Tabela Jogos'!$E$24))) -> 0 | G22: =SUM((('Tabela Jogos'!G20+'Tabela Jogos'!G22)+'Tabela Jogos'!E24)) -> 6 | H22: =SUM((('Tabela Jogos'!E20+'Tabela Jogos'!E22)+'Tabela Jogos'!G24)) -> 2 | I22: =SUM((G22-H22)) -> 4 | K22: =IF((B22<=B21),A22,A21) -> Marrocos | L22: =VLOOKUP(K22,$A$21:$I$24,2,FALSE) -> 7 | N22: =IF((L22>=L24),K22,K24) -> Marrocos | O22: =VLOOKUP(N22,$A$21:$I$24,2,FALSE) -> 7 | Q22: =IF((O22>=O23),N22,N23) -> Marrocos | R22: =VLOOKUP(Q22,$A$21:$I$24,2,FALSE) -> 7 | S22: =VLOOKUP(Q22,$A$21:$I$24,9,FALSE) -> 4 | U22: =IF(AND((R21=R22),(S22>S21)),Q21,Q22) -> Marrocos | V22: =VLOOKUP(U22,$A$21:$I$24,2,FALSE) -> 7 | W22: =VLOOKUP(U22,$A$21:$I$24,9,FALSE) -> 4 | X22: =IF(AND((V22=V24),(W24>W22)),U24,U22) -> Marrocos | Y22: =VLOOKUP(X22,$A$21:$I$24,2,FALSE) -> 7 | Z22: =VLOOKUP(X22,$A$21:$I$24,9,FALSE) -> 4 | AB22: =IF(AND((Y22=Y23),(Z23>Z22)),X23,X22) -> Marrocos | AC22: =VLOOKUP(AB22,$A$21:$I$24,2,FALSE) -> 7 | AD22: =VLOOKUP(AB22,$A$21:$I$24,9,FALSE) -> 4 | AE22: =VLOOKUP(AB22,$A$21:$I$24,7,FALSE) -> 6 | AF22: =IF(AND((AC22=AC21),(AD22=AD21),(AE22>AE21)),AB21,AB22) -> Marrocos | AG22: =VLOOKUP(AF22,$A$21:$I$24,2,FALSE) -> 7 | AH22: =VLOOKUP(AF22,$A$21:$I$24,9,FALSE) -> 4 | AI22: =VLOOKUP(AF22,$A$21:$I$24,7,FALSE) -> 6 | AJ22: =IF(AND((AG22=AG24),(AH22=AH24),(AI24>AI22)),AF24,AF22) -> Marrocos | AK22: =VLOOKUP(AJ22,$A$21:$I$24,2,FALSE) -> 7 | AL22: =VLOOKUP(AJ22,$A$21:$I$24,9,FALSE) -> 4 | AM22: =VLOOKUP(AJ22,$A$21:$I$24,7,FALSE) -> 6 | AN22: =IF(AND((AK22=AK23),(AL22=AL23),(AM23>AM22)),AJ23,AJ22) -> Marrocos | AO22: =VLOOKUP(AN22,$A$21:$I$24,2,FALSE) -> 7 | AP22: =VLOOKUP(AN22,$A$21:$I$24,9,FALSE) -> 4 | AQ22: =VLOOKUP(AN22,$A$21:$I$24,7,FALSE) -> 6
A23: Haiti | B23: =SUM((D23*3))+E23 -> 0 | C23: =COUNT('Tabela Jogos'!E21,'Tabela Jogos'!G23,'Tabela Jogos'!G24) -> 3 | D23: =SUM(IF(('Tabela Jogos'!$E$21>'Tabela Jogos'!$G$21),COUNT('Tabela Jogos'!$E$21)),IF(('Tabela Jogos'!$G$23>'Tabela Jogos'!$E$23),COUNT('Tabela Jogos'!$G$23)),IF(('Tabela Jogos'!$G$24>'Tabela Jogos'!$E$24),COUNT('Tabela Jogos'!$G$24))) -> 0 | E23: =SUM(IF(('Tabela Jogos'!$E$21='Tabela Jogos'!$G$21),COUNT('Tabela Jogos'!$E$21)),IF(('Tabela Jogos'!$G$23='Tabela Jogos'!$E$23),COUNT('Tabela Jogos'!$G$23)),IF(('Tabela Jogos'!$G$24='Tabela Jogos'!$E$24),COUNT('Tabela Jogos'!$G$24))) -> 0 | F23: =SUM(IF(('Tabela Jogos'!$E$21<'Tabela Jogos'!$G$21),COUNT('Tabela Jogos'!$E$21)),IF(('Tabela Jogos'!$G$23<'Tabela Jogos'!$E$23),COUNT('Tabela Jogos'!$G$23)),IF(('Tabela Jogos'!$G$24<'Tabela Jogos'!$E$24),COUNT('Tabela Jogos'!$G$24))) -> 3 | G23: =SUM((('Tabela Jogos'!E21+'Tabela Jogos'!G23)+'Tabela Jogos'!G24)) -> 1 | H23: =SUM((('Tabela Jogos'!G21+'Tabela Jogos'!E23)+'Tabela Jogos'!E24)) -> 10 | I23: =SUM((G23-H23)) -> -9 | K23: =IF((B23>=B24),A23,A24) -> Escócia | L23: =VLOOKUP(K23,$A$21:$I$24,2,FALSE) -> 3 | N23: =IF((L23<=L21),K23,K21) -> Escócia | O23: =VLOOKUP(N23,$A$21:$I$24,2,FALSE) -> 3 | Q23: =IF((O23<=O22),N23,N22) -> Escócia | R23: =VLOOKUP(Q23,$A$21:$I$24,2,FALSE) -> 3 | S23: =VLOOKUP(Q23,$A$21:$I$24,9,FALSE) -> -1 | U23: =IF(AND((R23=R24),(S24>S23)),Q24,Q23) -> Escócia | V23: =VLOOKUP(U23,$A$21:$I$24,2,FALSE) -> 3 | W23: =VLOOKUP(U23,$A$21:$I$24,9,FALSE) -> -1 | X23: =IF(AND((V21=V23),(W23>W21)),U21,U23) -> Escócia | Y23: =VLOOKUP(X23,$A$21:$I$24,2,FALSE) -> 3 | Z23: =VLOOKUP(X23,$A$21:$I$24,9,FALSE) -> -1 | AB23: =IF(AND((Y23=Y22),(Z23>Z22)),X22,X23) -> Escócia | AC23: =VLOOKUP(AB23,$A$21:$I$24,2,FALSE) -> 3 | AD23: =VLOOKUP(AB23,$A$21:$I$24,9,FALSE) -> -1 | AE23: =VLOOKUP(AB23,$A$21:$I$24,7,FALSE) -> 4 | AF23: =IF(AND((AC23=AC24),(AD23=AD24),(AE24>AE23)),AB24,AB23) -> Escócia | AG23: =VLOOKUP(AF23,$A$21:$I$24,2,FALSE) -> 3 | AH23: =VLOOKUP(AF23,$A$21:$I$24,9,FALSE) -> -1 | AI23: =VLOOKUP(AF23,$A$21:$I$24,7,FALSE) -> 4 | AJ23: =IF(AND((AG23=AG21),(AH23=AH21),(AI23>AI21)),AF21,AF23) -> Escócia | AK23: =VLOOKUP(AJ23,$A$21:$I$24,2,FALSE) -> 3 | AL23: =VLOOKUP(AJ23,$A$21:$I$24,9,FALSE) -> -1 | AM23: =VLOOKUP(AJ23,$A$21:$I$24,7,FALSE) -> 4 | AN23: =IF(AND((AK23=AK22),(AL23=AL22),(AM23>AM22)),AJ22,AJ23) -> Escócia | AO23: =VLOOKUP(AN23,$A$21:$I$24,2,FALSE) -> 3 | AP23: =VLOOKUP(AN23,$A$21:$I$24,9,FALSE) -> -1 | AQ23: =VLOOKUP(AN23,$A$21:$I$24,7,FALSE) -> 4
A24: Escócia | B24: =SUM((D24*3))+E24 -> 3 | C24: =COUNT('Tabela Jogos'!G21,'Tabela Jogos'!E22,'Tabela Jogos'!E25) -> 3 | D24: =SUM(IF(('Tabela Jogos'!$G$21>'Tabela Jogos'!$E$21),COUNT('Tabela Jogos'!$G$21)),IF(('Tabela Jogos'!$E$22>'Tabela Jogos'!$G$22),COUNT('Tabela Jogos'!$E$22)),IF(('Tabela Jogos'!$E$25>'Tabela Jogos'!$G$25),COUNT('Tabela Jogos'!$E$25))) -> 1 | E24: =SUM(IF(('Tabela Jogos'!$G$21='Tabela Jogos'!$E$21),COUNT('Tabela Jogos'!$G$21)),IF(('Tabela Jogos'!$E$22='Tabela Jogos'!$G$22),COUNT('Tabela Jogos'!$E$22)),IF(('Tabela Jogos'!$E$25='Tabela Jogos'!$G$25),COUNT('Tabela Jogos'!$E$25))) -> 0 | F24: =SUM(IF(('Tabela Jogos'!$G$21<'Tabela Jogos'!$E$21),COUNT('Tabela Jogos'!$G$21)),IF(('Tabela Jogos'!$E$22<'Tabela Jogos'!$G$22),COUNT('Tabela Jogos'!$E$22)),IF(('Tabela Jogos'!$E$25<'Tabela Jogos'!$G$25),COUNT('Tabela Jogos'!$E$25))) -> 2 | G24: =SUM((('Tabela Jogos'!G21+'Tabela Jogos'!E22)+'Tabela Jogos'!E25)) -> 4 | H24: =SUM((('Tabela Jogos'!E21+'Tabela Jogos'!G22)+'Tabela Jogos'!G25)) -> 5 | I24: =SUM((G24-H24)) -> -1 | K24: =IF((B24<=B23),A24,A23) -> Haiti | L24: =VLOOKUP(K24,$A$21:$I$24,2,FALSE) -> 0 | N24: =IF((L24<=L22),K24,K22) -> Haiti | O24: =VLOOKUP(N24,$A$21:$I$24,2,FALSE) -> 0 | Q24: =IF((O24<=O21),N24,N21) -> Haiti | R24: =VLOOKUP(Q24,$A$21:$I$24,2,FALSE) -> 0 | S24: =VLOOKUP(Q24,$A$21:$I$24,9,FALSE) -> -9 | U24: =IF(AND((R23=R24),(S24>S23)),Q23,Q24) -> Haiti | V24: =VLOOKUP(U24,$A$21:$I$24,2,FALSE) -> 0 | W24: =VLOOKUP(U24,$A$21:$I$24,9,FALSE) -> -9 | X24: =IF(AND((V22=V24),(W24>W22)),U22,U24) -> Haiti | Y24: =VLOOKUP(X24,$A$21:$I$24,2,FALSE) -> 0 | Z24: =VLOOKUP(X24,$A$21:$I$24,9,FALSE) -> -9 | AB24: =IF(AND((Y24=Y21),(Z24>Z21)),X21,X24) -> Haiti | AC24: =VLOOKUP(AB24,$A$21:$I$24,2,FALSE) -> 0 | AD24: =VLOOKUP(AB24,$A$21:$I$24,9,FALSE) -> -9 | AE24: =VLOOKUP(AB24,$A$21:$I$24,7,FALSE) -> 1 | AF24: =IF(AND((AC24=AC23),(AD24=AD23),(AE24>AE23)),X23,X24) -> Haiti | AG24: =VLOOKUP(AF24,$A$21:$I$24,2,FALSE) -> 0 | AH24: =VLOOKUP(AF24,$A$21:$I$24,9,FALSE) -> -9 | AI24: =VLOOKUP(AF24,$A$21:$I$24,7,FALSE) -> 1 | AJ24: =IF(AND((AG22=AG24),(AH22=AH24),(AI24>AI22)),AF22,AF24) -> Haiti | AK24: =VLOOKUP(AJ24,$A$21:$I$24,2,FALSE) -> 0 | AL24: =VLOOKUP(AJ24,$A$21:$I$24,9,FALSE) -> -9 | AM24: =VLOOKUP(AJ24,$A$21:$I$24,7,FALSE) -> 1 | AN24: =IF(AND((AK24=AK21),(AL24=AL21),(AM24>AM21)),AJ21,AJ24) -> Haiti | AO24: =VLOOKUP(AN24,$A$21:$I$24,2,FALSE) -> 0 | AP24: =VLOOKUP(AN24,$A$21:$I$24,9,FALSE) -> -9 | AQ24: =VLOOKUP(AN24,$A$21:$I$24,7,FALSE) -> 1
B27: Grupo D | K27: Pontos ganhos | N27: Pontos Ganhos | Q27: Saldo de gols | U27: Saldo de gols
A28: Seleção | B28: PT | C28: J | D28: V | E28: E | F28: D | G28: GP | H28: GC | I28: SG | L28: PT | O28: pt | R28: PT | S28: SG | V28: PT | W28: SG | Y28: PT | Z28: SG | AC28: PT | AD28: SG | AE28: GP | AG28: PT | AH28: SG | AI28: GP | AK28: PT | AL28: SG | AM28: GP | AO28: PT | AP28: SG | AQ28: GP
A29: Estados Unidos | B29: =SUM((D29*3))+E29 -> 6 | C29: =COUNT('Tabela Jogos'!E28,'Tabela Jogos'!E30,'Tabela Jogos'!G32) -> 3 | D29: =SUM(IF(('Tabela Jogos'!$E$28>'Tabela Jogos'!$G$28),COUNT('Tabela Jogos'!$E$28)),IF(('Tabela Jogos'!$E$30>'Tabela Jogos'!$G$30),COUNT('Tabela Jogos'!$E$30)),IF(('Tabela Jogos'!$G$32>'Tabela Jogos'!$E$32),COUNT('Tabela Jogos'!$G$32))) -> 2 | E29: =SUM(IF(('Tabela Jogos'!$E$28='Tabela Jogos'!$G$28),COUNT('Tabela Jogos'!$E$28)),IF(('Tabela Jogos'!$E$30='Tabela Jogos'!$G$30),COUNT('Tabela Jogos'!$E$30)),IF(('Tabela Jogos'!$G$32='Tabela Jogos'!$E$32),COUNT('Tabela Jogos'!$G$32))) -> 0 | F29: =SUM(IF(('Tabela Jogos'!$E$28<'Tabela Jogos'!$G$28),COUNT('Tabela Jogos'!$E$28)),IF(('Tabela Jogos'!$E$30<'Tabela Jogos'!$G$30),COUNT('Tabela Jogos'!$E$30)),IF(('Tabela Jogos'!$G$32<'Tabela Jogos'!$E$32),COUNT('Tabela Jogos'!$G$32))) -> 1 | G29: =SUM((('Tabela Jogos'!E28+'Tabela Jogos'!E30)+'Tabela Jogos'!G32)) -> 5 | H29: =SUM((('Tabela Jogos'!G28+'Tabela Jogos'!G30)+'Tabela Jogos'!E32)) -> 3 | I29: =SUM((G29-H29)) -> 2 | K29: =IF((B29>=B30),A29,A30) -> Estados Unidos | L29: =VLOOKUP(K29,$A$29:$I$32,2,FALSE) -> 6 | N29: =IF((L29>=L31),K29,K31) -> Turquia | O29: =VLOOKUP(N29,$A$29:$I$32,2,FALSE) -> 7 | Q29: =IF((O29>=O32),N29,N32) -> Turquia | R29: =VLOOKUP(Q29,$A$29:$I$32,2,FALSE) -> 7 | S29: =VLOOKUP(Q29,$A$29:$I$32,9,FALSE) -> 3 | U29: =IF(AND((R29=R30),(S30>S29)),Q30,Q29) -> Turquia | V29: =VLOOKUP(U29,$A$29:$I$32,2,FALSE) -> 7 | W29: =VLOOKUP(U29,$A$29:$I$32,9,FALSE) -> 3 | X29: =IF(AND((V29=V31),(W31>W29)),U31,U29) -> Turquia | Y29: =VLOOKUP(X29,$A$29:$I$32,2,FALSE) -> 7 | Z29: =VLOOKUP(X29,$A$29:$I$32,9,FALSE) -> 3 | AB29: =IF(AND((Y29=Y32),(Z32>Z29)),X32,X29) -> Turquia | AC29: =VLOOKUP(AB29,$A$29:$I$32,2,FALSE) -> 7 | AD29: =VLOOKUP(AB29,$A$29:$I$32,9,FALSE) -> 3 | AE29: =VLOOKUP(AB29,$A$29:$I$32,7,FALSE) -> 6 | AF29: =IF(AND((AC29=AC30),(AD29=AD30),(AE30>AE29)),AB30,AB29) -> Turquia | AG29: =VLOOKUP(AF29,$A$29:$I$32,2,FALSE) -> 7 | AH29: =VLOOKUP(AF29,$A$29:$I$32,9,FALSE) -> 3 | AI29: =VLOOKUP(AF29,$A$29:$I$32,7,FALSE) -> 6 | AJ29: =IF(AND((AG29=AG31),(AH29=AH31),(AI31>AI29)),AF31,AF29) -> Turquia | AK29: =VLOOKUP(AJ29,$A$29:$I$32,2,FALSE) -> 7 | AL29: =VLOOKUP(AJ29,$A$29:$I$32,9,FALSE) -> 3 | AM29: =VLOOKUP(AJ29,$A$29:$I$32,7,FALSE) -> 6 | AN29: =IF(AND((AK29=AK32),(AL29=AL32),(AM32>AM29)),AJ32,AJ29) -> Turquia | AO29: =VLOOKUP(AN29,$A$29:$I$32,2,FALSE) -> 7 | AP29: =VLOOKUP(AN29,$A$29:$I$32,9,FALSE) -> 3 | AQ29: =VLOOKUP(AN29,$A$29:$I$32,7,FALSE) -> 6
A30: Paraguai | B30: =SUM((D30*3))+E30 -> 4 | C30: =COUNT('Tabela Jogos'!G28,'Tabela Jogos'!G31,'Tabela Jogos'!E33) -> 3 | D30: =SUM(IF(('Tabela Jogos'!$G$28>'Tabela Jogos'!$E$28),COUNT('Tabela Jogos'!$G$28)),IF(('Tabela Jogos'!$G$31>'Tabela Jogos'!$E$31),COUNT('Tabela Jogos'!$G$31)),IF(('Tabela Jogos'!$E$33>'Tabela Jogos'!$G$33),COUNT('Tabela Jogos'!$E$33))) -> 1 | E30: =SUM(IF(('Tabela Jogos'!$G$28='Tabela Jogos'!$E$28),COUNT('Tabela Jogos'!$G$28)),IF(('Tabela Jogos'!$G$31='Tabela Jogos'!$E$31),COUNT('Tabela Jogos'!$G$31)),IF(('Tabela Jogos'!$E$33='Tabela Jogos'!$G$33),COUNT('Tabela Jogos'!$E$33))) -> 1 | F30: =SUM(IF(('Tabela Jogos'!$G$28<'Tabela Jogos'!$E$28),COUNT('Tabela Jogos'!$G$28)),IF(('Tabela Jogos'!$G$31<'Tabela Jogos'!$E$31),COUNT('Tabela Jogos'!$G$31)),IF(('Tabela Jogos'!$E$33<'Tabela Jogos'!$G$33),COUNT('Tabela Jogos'!$E$33))) -> 1 | G30: =SUM((('Tabela Jogos'!G28+'Tabela Jogos'!G31)+'Tabela Jogos'!E33)) -> 4 | H30: =SUM((('Tabela Jogos'!E28+'Tabela Jogos'!E31)+'Tabela Jogos'!G33)) -> 4 | I30: =SUM((G30-H30)) -> 0 | K30: =IF((B30<=B29),A30,A29) -> Paraguai | L30: =VLOOKUP(K30,$A$29:$I$32,2,FALSE) -> 4 | N30: =IF((L30>=L32),K30,K32) -> Paraguai | O30: =VLOOKUP(N30,$A$29:$I$32,2,FALSE) -> 4 | Q30: =IF((O30>=O31),N30,N31) -> Estados Unidos | R30: =VLOOKUP(Q30,$A$29:$I$32,2,FALSE) -> 6 | S30: =VLOOKUP(Q30,$A$29:$I$32,9,FALSE) -> 2 | U30: =IF(AND((R29=R30),(S30>S29)),Q29,Q30) -> Estados Unidos | V30: =VLOOKUP(U30,$A$29:$I$32,2,FALSE) -> 6 | W30: =VLOOKUP(U30,$A$29:$I$32,9,FALSE) -> 2 | X30: =IF(AND((V30=V32),(W32>W30)),U32,U30) -> Estados Unidos | Y30: =VLOOKUP(X30,$A$29:$I$32,2,FALSE) -> 6 | Z30: =VLOOKUP(X30,$A$29:$I$32,9,FALSE) -> 2 | AB30: =IF(AND((Y30=Y31),(Z31>Z30)),X31,X30) -> Estados Unidos | AC30: =VLOOKUP(AB30,$A$29:$I$32,2,FALSE) -> 6 | AD30: =VLOOKUP(AB30,$A$29:$I$32,9,FALSE) -> 2 | AE30: =VLOOKUP(AB30,$A$29:$I$32,7,FALSE) -> 5 | AF30: =IF(AND((AC30=AC29),(AD30=AD29),(AE30>AE29)),AB29,AB30) -> Estados Unidos | AG30: =VLOOKUP(AF30,$A$29:$I$32,2,FALSE) -> 6 | AH30: =VLOOKUP(AF30,$A$29:$I$32,9,FALSE) -> 2 | AI30: =VLOOKUP(AF30,$A$29:$I$32,7,FALSE) -> 5 | AJ30: =IF(AND((AG30=AG32),(AH30=AH32),(AI32>AI30)),AF32,AF30) -> Estados Unidos | AK30: =VLOOKUP(AJ30,$A$29:$I$32,2,FALSE) -> 6 | AL30: =VLOOKUP(AJ30,$A$29:$I$32,9,FALSE) -> 2 | AM30: =VLOOKUP(AJ30,$A$29:$I$32,7,FALSE) -> 5 | AN30: =IF(AND((AK30=AK31),(AL30=AL31),(AM31>AM30)),AJ31,AJ30) -> Estados Unidos | AO30: =VLOOKUP(AN30,$A$29:$I$32,2,FALSE) -> 6 | AP30: =VLOOKUP(AN30,$A$29:$I$32,9,FALSE) -> 2 | AQ30: =VLOOKUP(AN30,$A$29:$I$32,7,FALSE) -> 5
A31: Austrália | B31: =SUM((D31*3))+E31 -> 0 | C31: =COUNT('Tabela Jogos'!E29,'Tabela Jogos'!G30,'Tabela Jogos'!G33) -> 3 | D31: =SUM(IF(('Tabela Jogos'!$E$29>'Tabela Jogos'!$G$29),COUNT('Tabela Jogos'!$E$29)),IF(('Tabela Jogos'!$G$30>'Tabela Jogos'!$E$30),COUNT('Tabela Jogos'!$G$30)),IF(('Tabela Jogos'!$G$33>'Tabela Jogos'!$E$33),COUNT('Tabela Jogos'!$G$33))) -> 0 | E31: =SUM(IF(('Tabela Jogos'!$E$29='Tabela Jogos'!$G$29),COUNT('Tabela Jogos'!$E$29)),IF(('Tabela Jogos'!$G$30='Tabela Jogos'!$E$30),COUNT('Tabela Jogos'!$G$30)),IF(('Tabela Jogos'!$G$33='Tabela Jogos'!$E$33),COUNT('Tabela Jogos'!$G$33))) -> 0 | F31: =SUM(IF(('Tabela Jogos'!$E$29<'Tabela Jogos'!$G$29),COUNT('Tabela Jogos'!$E$29)),IF(('Tabela Jogos'!$G$30<'Tabela Jogos'!$E$30),COUNT('Tabela Jogos'!$G$30)),IF(('Tabela Jogos'!$G$33<'Tabela Jogos'!$E$33),COUNT('Tabela Jogos'!$G$33))) -> 3 | G31: =SUM((('Tabela Jogos'!E29+'Tabela Jogos'!G30)+'Tabela Jogos'!G33)) -> 2 | H31: =SUM((('Tabela Jogos'!G29+'Tabela Jogos'!E30)+'Tabela Jogos'!E33)) -> 7 | I31: =SUM((G31-H31)) -> -5 | K31: =IF((B31>=B32),A31,A32) -> Turquia | L31: =VLOOKUP(K31,$A$29:$I$32,2,FALSE) -> 7 | N31: =IF((L31<=L29),K31,K29) -> Estados Unidos | O31: =VLOOKUP(N31,$A$29:$I$32,2,FALSE) -> 6 | Q31: =IF((O31<=O30),N31,N30) -> Paraguai | R31: =VLOOKUP(Q31,$A$29:$I$32,2,FALSE) -> 4 | S31: =VLOOKUP(Q31,$A$29:$I$32,9,FALSE) -> 0 | U31: =IF(AND((R31=R32),(S32>S31)),Q32,Q31) -> Paraguai | V31: =VLOOKUP(U31,$A$29:$I$32,2,FALSE) -> 4 | W31: =VLOOKUP(U31,$A$29:$I$32,9,FALSE) -> 0 | X31: =IF(AND((V29=V31),(W31>W29)),U29,U31) -> Paraguai | Y31: =VLOOKUP(X31,$A$29:$I$32,2,FALSE) -> 4 | Z31: =VLOOKUP(X31,$A$29:$I$32,9,FALSE) -> 0 | AB31: =IF(AND((Y31=Y30),(Z31>Z30)),X30,X31) -> Paraguai | AC31: =VLOOKUP(AB31,$A$29:$I$32,2,FALSE) -> 4 | AD31: =VLOOKUP(AB31,$A$29:$I$32,9,FALSE) -> 0 | AE31: =VLOOKUP(AB31,$A$29:$I$32,7,FALSE) -> 4 | AF31: =IF(AND((AC31=AC32),(AD31=AD32),(AE32>AE31)),AB32,AB31) -> Paraguai | AG31: =VLOOKUP(AF31,$A$29:$I$32,2,FALSE) -> 4 | AH31: =VLOOKUP(AF31,$A$29:$I$32,9,FALSE) -> 0 | AI31: =VLOOKUP(AF31,$A$29:$I$32,7,FALSE) -> 4 | AJ31: =IF(AND((AG31=AG29),(AH31=AH29),(AI31>AI29)),AF29,AF31) -> Paraguai | AK31: =VLOOKUP(AJ31,$A$29:$I$32,2,FALSE) -> 4 | AL31: =VLOOKUP(AJ31,$A$29:$I$32,9,FALSE) -> 0 | AM31: =VLOOKUP(AJ31,$A$29:$I$32,7,FALSE) -> 4 | AN31: =IF(AND((AK31=AK30),(AL31=AL30),(AM31>AM30)),AJ30,AJ31) -> Paraguai | AO31: =VLOOKUP(AN31,$A$29:$I$32,2,FALSE) -> 4 | AP31: =VLOOKUP(AN31,$A$29:$I$32,9,FALSE) -> 0 | AQ31: =VLOOKUP(AN31,$A$29:$I$32,7,FALSE) -> 4
A32: Turquia | B32: =SUM((D32*3))+E32 -> 7 | C32: =COUNT('Tabela Jogos'!G29,'Tabela Jogos'!E31,'Tabela Jogos'!E32) -> 3 | D32: =SUM(IF(('Tabela Jogos'!$G$29>'Tabela Jogos'!$E$29),COUNT('Tabela Jogos'!$G$29)),IF(('Tabela Jogos'!$E$31>'Tabela Jogos'!$G$31),COUNT('Tabela Jogos'!$E$31)),IF(('Tabela Jogos'!$E$32>'Tabela Jogos'!$G$32),COUNT('Tabela Jogos'!$E$32))) -> 2 | E32: =SUM(IF(('Tabela Jogos'!$G$29='Tabela Jogos'!$E$29),COUNT('Tabela Jogos'!$G$29)),IF(('Tabela Jogos'!$E$31='Tabela Jogos'!$G$31),COUNT('Tabela Jogos'!$E$31)),IF(('Tabela Jogos'!$E$32='Tabela Jogos'!$G$32),COUNT('Tabela Jogos'!$E$32))) -> 1 | F32: =SUM(IF(('Tabela Jogos'!$G$29<'Tabela Jogos'!$E$29),COUNT('Tabela Jogos'!$G$29)),IF(('Tabela Jogos'!$E$31<'Tabela Jogos'!$G$31),COUNT('Tabela Jogos'!$E$31)),IF(('Tabela Jogos'!$E$32<'Tabela Jogos'!$G$32),COUNT('Tabela Jogos'!$E$32))) -> 0 | G32: =SUM((('Tabela Jogos'!G29+'Tabela Jogos'!E31)+'Tabela Jogos'!E32)) -> 6 | H32: =SUM((('Tabela Jogos'!E29+'Tabela Jogos'!G31)+'Tabela Jogos'!G32)) -> 3 | I32: =SUM((G32-H32)) -> 3 | K32: =IF((B32<=B31),A32,A31) -> Austrália | L32: =VLOOKUP(K32,$A$29:$I$32,2,FALSE) -> 0 | N32: =IF((L32<=L30),K32,K30) -> Austrália | O32: =VLOOKUP(N32,$A$29:$I$32,2,FALSE) -> 0 | Q32: =IF((O32<=O29),N32,N29) -> Austrália | R32: =VLOOKUP(Q32,$A$29:$I$32,2,FALSE) -> 0 | S32: =VLOOKUP(Q32,$A$29:$I$32,9,FALSE) -> -5 | U32: =IF(AND((R31=R32),(S32>S31)),Q31,Q32) -> Austrália | V32: =VLOOKUP(U32,$A$29:$I$32,2,FALSE) -> 0 | W32: =VLOOKUP(U32,$A$29:$I$32,9,FALSE) -> -5 | X32: =IF(AND((V30=V32),(W32>W30)),U30,U32) -> Austrália | Y32: =VLOOKUP(X32,$A$29:$I$32,2,FALSE) -> 0 | Z32: =VLOOKUP(X32,$A$29:$I$32,9,FALSE) -> -5 | AB32: =IF(AND((Y32=Y29),(Z32>Z29)),X29,X32) -> Austrália | AC32: =VLOOKUP(AB32,$A$29:$I$32,2,FALSE) -> 0 | AD32: =VLOOKUP(AB32,$A$29:$I$32,9,FALSE) -> -5 | AE32: =VLOOKUP(AB32,$A$29:$I$32,7,FALSE) -> 2 | AF32: =IF(AND((AC32=AC31),(AD32=AD31),(AE32>AE31)),X31,X32) -> Austrália | AG32: =VLOOKUP(AF32,$A$29:$I$32,2,FALSE) -> 0 | AH32: =VLOOKUP(AF32,$A$29:$I$32,9,FALSE) -> -5 | AI32: =VLOOKUP(AF32,$A$29:$I$32,7,FALSE) -> 2 | AJ32: =IF(AND((AG30=AG32),(AH30=AH32),(AI32>AI30)),AF30,AF32) -> Austrália | AK32: =VLOOKUP(AJ32,$A$29:$I$32,2,FALSE) -> 0 | AL32: =VLOOKUP(AJ32,$A$29:$I$32,9,FALSE) -> -5 | AM32: =VLOOKUP(AJ32,$A$29:$I$32,7,FALSE) -> 2 | AN32: =IF(AND((AK32=AK29),(AL32=AL29),(AM32>AM29)),AJ29,AJ32) -> Austrália | AO32: =VLOOKUP(AN32,$A$29:$I$32,2,FALSE) -> 0 | AP32: =VLOOKUP(AN32,$A$29:$I$32,9,FALSE) -> -5 | AQ32: =VLOOKUP(AN32,$A$29:$I$32,7,FALSE) -> 2
B35: Grupo E | K35: Pontos ganhos | N35: Pontos Ganhos | Q35: Saldo de gols | U35: Saldo de gols
A36: Seleção | B36: PT | C36: J | D36: V | E36: E | F36: D | G36: GP | H36: GC | I36: SG | L36: PT | O36: pt | R36: PT | S36: SG | V36: PT | W36: SG | Y36: PT | Z36: SG | AC36: PT | AD36: SG | AE36: GP | AG36: PT | AH36: SG | AI36: GP | AK36: PT | AL36: SG | AM36: GP | AO36: PT | AP36: SG | AQ36: GP
A37: Alemanha | B37: =SUM((D37*3))+E37 -> 9 | C37: =COUNT('Tabela Jogos'!E36,'Tabela Jogos'!E38,'Tabela Jogos'!G40) -> 3 | D37: =SUM(IF(('Tabela Jogos'!$E$36>'Tabela Jogos'!$G$36),COUNT('Tabela Jogos'!$E$36)),IF(('Tabela Jogos'!$E$38>'Tabela Jogos'!$G$38),COUNT('Tabela Jogos'!$E$38)),IF(('Tabela Jogos'!$G$40>'Tabela Jogos'!$E$40),COUNT('Tabela Jogos'!$G$40))) -> 3 | E37: =SUM(IF(('Tabela Jogos'!$E$36='Tabela Jogos'!$G$36),COUNT('Tabela Jogos'!$E$36)),IF(('Tabela Jogos'!$E$38='Tabela Jogos'!$G$38),COUNT('Tabela Jogos'!$E$38)),IF(('Tabela Jogos'!$G$40='Tabela Jogos'!$E$40),COUNT('Tabela Jogos'!$G$40))) -> 0 | F37: =SUM(IF(('Tabela Jogos'!$E$36<'Tabela Jogos'!$G$36),COUNT('Tabela Jogos'!$E$36)),IF(('Tabela Jogos'!$E$38<'Tabela Jogos'!$G$38),COUNT('Tabela Jogos'!$E$38)),IF(('Tabela Jogos'!$G$40<'Tabela Jogos'!$E$40),COUNT('Tabela Jogos'!$G$40))) -> 0 | G37: =SUM((('Tabela Jogos'!E36+'Tabela Jogos'!E38)+'Tabela Jogos'!G40)) -> 9 | H37: =SUM((('Tabela Jogos'!G36+'Tabela Jogos'!G38)+'Tabela Jogos'!E40)) -> 2 | I37: =SUM((G37-H37)) -> 7 | K37: =IF((B37>=B38),A37,A38) -> Alemanha | L37: =VLOOKUP(K37,$A$37:$I$40,2,FALSE) -> 9 | N37: =IF((L37>=L39),K37,K39) -> Alemanha | O37: =VLOOKUP(N37,$A$37:$I$40,2,FALSE) -> 9 | Q37: =IF((O37>=O40),N37,N40) -> Alemanha | R37: =VLOOKUP(Q37,$A$37:$I$40,2,FALSE) -> 9 | S37: =VLOOKUP(Q37,$A$37:$I$40,9,FALSE) -> 7 | U37: =IF(AND((R37=R38),(S38>S37)),Q38,Q37) -> Alemanha | V37: =VLOOKUP(U37,$A$37:$I$40,2,FALSE) -> 9 | W37: =VLOOKUP(U37,$A$37:$I$40,9,FALSE) -> 7 | X37: =IF(AND((V37=V39),(W39>W37)),U39,U37) -> Alemanha | Y37: =VLOOKUP(X37,$A$37:$I$40,2,FALSE) -> 9 | Z37: =VLOOKUP(X37,$A$37:$I$40,9,FALSE) -> 7 | AB37: =IF(AND((Y37=Y40),(Z40>Z37)),X40,X37) -> Alemanha | AC37: =VLOOKUP(AB37,$A$37:$I$40,2,FALSE) -> 9 | AD37: =VLOOKUP(AB37,$A$37:$I$40,9,FALSE) -> 7 | AE37: =VLOOKUP(AB37,$A$37:$I$40,7,FALSE) -> 9 | AF37: =IF(AND((AC37=AC38),(AD37=AD38),(AE38>AE37)),AB38,AB37) -> Alemanha | AG37: =VLOOKUP(AF37,$A$37:$I$40,2,FALSE) -> 9 | AH37: =VLOOKUP(AF37,$A$37:$I$40,9,FALSE) -> 7 | AI37: =VLOOKUP(AF37,$A$37:$I$40,7,FALSE) -> 9 | AJ37: =IF(AND((AG37=AG39),(AH37=AH39),(AI39>AI37)),AF39,AF37) -> Alemanha | AK37: =VLOOKUP(AJ37,$A$37:$I$40,2,FALSE) -> 9 | AL37: =VLOOKUP(AJ37,$A$37:$I$40,9,FALSE) -> 7 | AM37: =VLOOKUP(AJ37,$A$37:$I$40,7,FALSE) -> 9 | AN37: =IF(AND((AK37=AK40),(AL37=AL40),(AM40>AM37)),AJ40,AJ37) -> Alemanha | AO37: =VLOOKUP(AN37,$A$37:$I$40,2,FALSE) -> 9 | AP37: =VLOOKUP(AN37,$A$37:$I$40,9,FALSE) -> 7 | AQ37: =VLOOKUP(AN37,$A$37:$I$40,7,FALSE) -> 9
A38: Curaçao | B38: =SUM((D38*3))+E38 -> 0 | C38: =COUNT('Tabela Jogos'!G36,'Tabela Jogos'!G39,'Tabela Jogos'!E41) -> 3 | D38: =SUM(IF(('Tabela Jogos'!$G$36>'Tabela Jogos'!$E$36),COUNT('Tabela Jogos'!$G$36)),IF(('Tabela Jogos'!$G$39>'Tabela Jogos'!$E$39),COUNT('Tabela Jogos'!$G$39)),IF(('Tabela Jogos'!$E$41>'Tabela Jogos'!$G$41),COUNT('Tabela Jogos'!$E$41))) -> 0 | E38: =SUM(IF(('Tabela Jogos'!$G$36='Tabela Jogos'!$E$36),COUNT('Tabela Jogos'!$G$36)),IF(('Tabela Jogos'!$G$39='Tabela Jogos'!$E$39),COUNT('Tabela Jogos'!$G$39)),IF(('Tabela Jogos'!$E$41='Tabela Jogos'!$G$41),COUNT('Tabela Jogos'!$E$41))) -> 0 | F38: =SUM(IF(('Tabela Jogos'!$G$36<'Tabela Jogos'!$E$36),COUNT('Tabela Jogos'!$G$36)),IF(('Tabela Jogos'!$G$39<'Tabela Jogos'!$E$39),COUNT('Tabela Jogos'!$G$39)),IF(('Tabela Jogos'!$E$41<'Tabela Jogos'!$G$41),COUNT('Tabela Jogos'!$E$41))) -> 3 | G38: =SUM((('Tabela Jogos'!G36+'Tabela Jogos'!G39)+'Tabela Jogos'!E41)) -> 0 | H38: =SUM((('Tabela Jogos'!E36+'Tabela Jogos'!E39)+'Tabela Jogos'!G41)) -> 11 | I38: =SUM((G38-H38)) -> -11 | K38: =IF((B38<=B37),A38,A37) -> Curaçao | L38: =VLOOKUP(K38,$A$37:$I$40,2,FALSE) -> 0 | N38: =IF((L38>=L40),K38,K40) -> Equador | O38: =VLOOKUP(N38,$A$37:$I$40,2,FALSE) -> 4 | Q38: =IF((O38>=O39),N38,N39) -> Equador | R38: =VLOOKUP(Q38,$A$37:$I$40,2,FALSE) -> 4 | S38: =VLOOKUP(Q38,$A$37:$I$40,9,FALSE) -> 2 | U38: =IF(AND((R37=R38),(S38>S37)),Q37,Q38) -> Equador | V38: =VLOOKUP(U38,$A$37:$I$40,2,FALSE) -> 4 | W38: =VLOOKUP(U38,$A$37:$I$40,9,FALSE) -> 2 | X38: =IF(AND((V38=V40),(W40>W38)),U40,U38) -> Equador | Y38: =VLOOKUP(X38,$A$37:$I$40,2,FALSE) -> 4 | Z38: =VLOOKUP(X38,$A$37:$I$40,9,FALSE) -> 2 | AB38: =IF(AND((Y38=Y39),(Z39>Z38)),X39,X38) -> Equador | AC38: =VLOOKUP(AB38,$A$37:$I$40,2,FALSE) -> 4 | AD38: =VLOOKUP(AB38,$A$37:$I$40,9,FALSE) -> 2 | AE38: =VLOOKUP(AB38,$A$37:$I$40,7,FALSE) -> 6 | AF38: =IF(AND((AC38=AC37),(AD38=AD37),(AE38>AE37)),AB37,AB38) -> Equador | AG38: =VLOOKUP(AF38,$A$37:$I$40,2,FALSE) -> 4 | AH38: =VLOOKUP(AF38,$A$37:$I$40,9,FALSE) -> 2 | AI38: =VLOOKUP(AF38,$A$37:$I$40,7,FALSE) -> 6 | AJ38: =IF(AND((AG38=AG40),(AH38=AH40),(AI40>AI38)),AF40,AF38) -> Equador | AK38: =VLOOKUP(AJ38,$A$37:$I$40,2,FALSE) -> 4 | AL38: =VLOOKUP(AJ38,$A$37:$I$40,9,FALSE) -> 2 | AM38: =VLOOKUP(AJ38,$A$37:$I$40,7,FALSE) -> 6 | AN38: =IF(AND((AK38=AK39),(AL38=AL39),(AM39>AM38)),AJ39,AJ38) -> Equador | AO38: =VLOOKUP(AN38,$A$37:$I$40,2,FALSE) -> 4 | AP38: =VLOOKUP(AN38,$A$37:$I$40,9,FALSE) -> 2 | AQ38: =VLOOKUP(AN38,$A$37:$I$40,7,FALSE) -> 6
A39: Costa do Marfim | B39: =SUM((D39*3))+E39 -> 4 | C39: =COUNT('Tabela Jogos'!E37,'Tabela Jogos'!G38,'Tabela Jogos'!G41) -> 3 | D39: =SUM(IF(('Tabela Jogos'!$E$37>'Tabela Jogos'!$G$37),COUNT('Tabela Jogos'!$E$37)),IF(('Tabela Jogos'!$G$38>'Tabela Jogos'!$E$38),COUNT('Tabela Jogos'!$G$38)),IF(('Tabela Jogos'!$G$41>'Tabela Jogos'!$E$41),COUNT('Tabela Jogos'!$G$41))) -> 1 | E39: =SUM(IF(('Tabela Jogos'!$E$37='Tabela Jogos'!$G$37),COUNT('Tabela Jogos'!$E$37)),IF(('Tabela Jogos'!$G$38='Tabela Jogos'!$E$38),COUNT('Tabela Jogos'!$G$38)),IF(('Tabela Jogos'!$G$41='Tabela Jogos'!$E$41),COUNT('Tabela Jogos'!$G$41))) -> 1 | F39: =SUM(IF(('Tabela Jogos'!$E$37<'Tabela Jogos'!$G$37),COUNT('Tabela Jogos'!$E$37)),IF(('Tabela Jogos'!$G$38<'Tabela Jogos'!$E$38),COUNT('Tabela Jogos'!$G$38)),IF(('Tabela Jogos'!$G$41<'Tabela Jogos'!$E$41),COUNT('Tabela Jogos'!$G$41))) -> 1 | G39: =SUM((('Tabela Jogos'!E37+'Tabela Jogos'!G38)+'Tabela Jogos'!G41)) -> 6 | H39: =SUM((('Tabela Jogos'!G37+'Tabela Jogos'!E38)+'Tabela Jogos'!E41)) -> 4 | I39: =SUM((G39-H39)) -> 2 | K39: =IF((B39>=B40),A39,A40) -> Costa do Marfim | L39: =VLOOKUP(K39,$A$37:$I$40,2,FALSE) -> 4 | N39: =IF((L39<=L37),K39,K37) -> Costa do Marfim | O39: =VLOOKUP(N39,$A$37:$I$40,2,FALSE) -> 4 | Q39: =IF((O39<=O38),N39,N38) -> Costa do Marfim | R39: =VLOOKUP(Q39,$A$37:$I$40,2,FALSE) -> 4 | S39: =VLOOKUP(Q39,$A$37:$I$40,9,FALSE) -> 2 | U39: =IF(AND((R39=R40),(S40>S39)),Q40,Q39) -> Costa do Marfim | V39: =VLOOKUP(U39,$A$37:$I$40,2,FALSE) -> 4 | W39: =VLOOKUP(U39,$A$37:$I$40,9,FALSE) -> 2 | X39: =IF(AND((V37=V39),(W39>W37)),U37,U39) -> Costa do Marfim | Y39: =VLOOKUP(X39,$A$37:$I$40,2,FALSE) -> 4 | Z39: =VLOOKUP(X39,$A$37:$I$40,9,FALSE) -> 2 | AB39: =IF(AND((Y39=Y38),(Z39>Z38)),X38,X39) -> Costa do Marfim | AC39: =VLOOKUP(AB39,$A$37:$I$40,2,FALSE) -> 4 | AD39: =VLOOKUP(AB39,$A$37:$I$40,9,FALSE) -> 2 | AE39: =VLOOKUP(AB39,$A$37:$I$40,7,FALSE) -> 6 | AF39: =IF(AND((AC39=AC40),(AD39=AD40),(AE40>AE39)),AB40,AB39) -> Costa do Marfim | AG39: =VLOOKUP(AF39,$A$37:$I$40,2,FALSE) -> 4 | AH39: =VLOOKUP(AF39,$A$37:$I$40,9,FALSE) -> 2 | AI39: =VLOOKUP(AF39,$A$37:$I$40,7,FALSE) -> 6 | AJ39: =IF(AND((AG39=AG37),(AH39=AH37),(AI39>AI37)),AF37,AF39) -> Costa do Marfim | AK39: =VLOOKUP(AJ39,$A$37:$I$40,2,FALSE) -> 4 | AL39: =VLOOKUP(AJ39,$A$37:$I$40,9,FALSE) -> 2 | AM39: =VLOOKUP(AJ39,$A$37:$I$40,7,FALSE) -> 6 | AN39: =IF(AND((AK39=AK38),(AL39=AL38),(AM39>AM38)),AJ38,AJ39) -> Costa do Marfim | AO39: =VLOOKUP(AN39,$A$37:$I$40,2,FALSE) -> 4 | AP39: =VLOOKUP(AN39,$A$37:$I$40,9,FALSE) -> 2 | AQ39: =VLOOKUP(AN39,$A$37:$I$40,7,FALSE) -> 6
A40: Equador | B40: =SUM((D40*3))+E40 -> 4 | C40: =COUNT('Tabela Jogos'!G37,'Tabela Jogos'!E39,'Tabela Jogos'!E40) -> 3 | D40: =SUM(IF(('Tabela Jogos'!$G$37>'Tabela Jogos'!$E$37),COUNT('Tabela Jogos'!$G$37)),IF(('Tabela Jogos'!$E$39>'Tabela Jogos'!$G$39),COUNT('Tabela Jogos'!$E$39)),IF(('Tabela Jogos'!$E$40>'Tabela Jogos'!$G$40),COUNT('Tabela Jogos'!$E$40))) -> 1 | E40: =SUM(IF(('Tabela Jogos'!$G$37='Tabela Jogos'!$E$37),COUNT('Tabela Jogos'!$G$37)),IF(('Tabela Jogos'!$E$39='Tabela Jogos'!$G$39),COUNT('Tabela Jogos'!$E$39)),IF(('Tabela Jogos'!$E$40='Tabela Jogos'!$G$40),COUNT('Tabela Jogos'!$E$40))) -> 1 | F40: =SUM(IF(('Tabela Jogos'!$G$37<'Tabela Jogos'!$E$37),COUNT('Tabela Jogos'!$G$37)),IF(('Tabela Jogos'!$E$39<'Tabela Jogos'!$G$39),COUNT('Tabela Jogos'!$E$39)),IF(('Tabela Jogos'!$E$40<'Tabela Jogos'!$G$40),COUNT('Tabela Jogos'!$E$40))) -> 1 | G40: =SUM((('Tabela Jogos'!G37+'Tabela Jogos'!E39)+'Tabela Jogos'!E40)) -> 6 | H40: =SUM((('Tabela Jogos'!E37+'Tabela Jogos'!G39)+'Tabela Jogos'!G40)) -> 4 | I40: =SUM((G40-H40)) -> 2 | K40: =IF((B40<=B39),A40,A39) -> Equador | L40: =VLOOKUP(K40,$A$37:$I$40,2,FALSE) -> 4 | N40: =IF((L40<=L38),K40,K38) -> Curaçao | O40: =VLOOKUP(N40,$A$37:$I$40,2,FALSE) -> 0 | Q40: =IF((O40<=O37),N40,N37) -> Curaçao | R40: =VLOOKUP(Q40,$A$37:$I$40,2,FALSE) -> 0 | S40: =VLOOKUP(Q40,$A$37:$I$40,9,FALSE) -> -11 | U40: =IF(AND((R39=R40),(S40>S39)),Q39,Q40) -> Curaçao | V40: =VLOOKUP(U40,$A$37:$I$40,2,FALSE) -> 0 | W40: =VLOOKUP(U40,$A$37:$I$40,9,FALSE) -> -11 | X40: =IF(AND((V38=V40),(W40>W38)),U38,U40) -> Curaçao | Y40: =VLOOKUP(X40,$A$37:$I$40,2,FALSE) -> 0 | Z40: =VLOOKUP(X40,$A$37:$I$40,9,FALSE) -> -11 | AB40: =IF(AND((Y40=Y37),(Z40>Z37)),X37,X40) -> Curaçao | AC40: =VLOOKUP(AB40,$A$37:$I$40,2,FALSE) -> 0 | AD40: =VLOOKUP(AB40,$A$37:$I$40,9,FALSE) -> -11 | AE40: =VLOOKUP(AB40,$A$37:$I$40,7,FALSE) -> 0 | AF40: =IF(AND((AC40=AC39),(AD40=AD39),(AE40>AE39)),X39,X40) -> Curaçao | AG40: =VLOOKUP(AF40,$A$37:$I$40,2,FALSE) -> 0 | AH40: =VLOOKUP(AF40,$A$37:$I$40,9,FALSE) -> -11 | AI40: =VLOOKUP(AF40,$A$37:$I$40,7,FALSE) -> 0 | AJ40: =IF(AND((AG38=AG40),(AH38=AH40),(AI40>AI38)),AF38,AF40) -> Curaçao | AK40: =VLOOKUP(AJ40,$A$37:$I$40,2,FALSE) -> 0 | AL40: =VLOOKUP(AJ40,$A$37:$I$40,9,FALSE) -> -11 | AM40: =VLOOKUP(AJ40,$A$37:$I$40,7,FALSE) -> 0 | AN40: =IF(AND((AK40=AK37),(AL40=AL37),(AM40>AM37)),AJ37,AJ40) -> Curaçao | AO40: =VLOOKUP(AN40,$A$37:$I$40,2,FALSE) -> 0 | AP40: =VLOOKUP(AN40,$A$37:$I$40,9,FALSE) -> -11 | AQ40: =VLOOKUP(AN40,$A$37:$I$40,7,FALSE) -> 0
B43: Grupo F | K43: Pontos ganhos | N43: Pontos Ganhos | Q43: Saldo de gols | U43: Saldo de gols
A44: Seleção | B44: PT | C44: J | D44: V | E44: E | F44: D | G44: GP | H44: GC | I44: SG | L44: PT | O44: pt | R44: PT | S44: SG | V44: PT | W44: SG | Y44: PT | Z44: SG | AC44: PT | AD44: SG | AE44: GP | AG44: PT | AH44: SG | AI44: GP | AK44: PT | AL44: SG | AM44: GP | AO44: PT | AP44: SG | AQ44: GP
A45: Holanda | B45: =SUM((D45*3))+E45 -> 9 | C45: =COUNT('Tabela Jogos'!E44,'Tabela Jogos'!E46,'Tabela Jogos'!G48) -> 3 | D45: =SUM(IF(('Tabela Jogos'!$E$44>'Tabela Jogos'!$G$44),COUNT('Tabela Jogos'!$E$44)),IF(('Tabela Jogos'!$E$46>'Tabela Jogos'!$G$46),COUNT('Tabela Jogos'!$E$46)),IF(('Tabela Jogos'!$G$48>'Tabela Jogos'!$E$48),COUNT('Tabela Jogos'!$G$48))) -> 3 | E45: =SUM(IF(('Tabela Jogos'!$E$44='Tabela Jogos'!$G$44),COUNT('Tabela Jogos'!$E$44)),IF(('Tabela Jogos'!$E$46='Tabela Jogos'!$G$46),COUNT('Tabela Jogos'!$E$46)),IF(('Tabela Jogos'!$G$48='Tabela Jogos'!$E$48),COUNT('Tabela Jogos'!$G$48))) -> 0 | F45: =SUM(IF(('Tabela Jogos'!$E$44<'Tabela Jogos'!$G$44),COUNT('Tabela Jogos'!$E$44)),IF(('Tabela Jogos'!$E$46<'Tabela Jogos'!$G$46),COUNT('Tabela Jogos'!$E$46)),IF(('Tabela Jogos'!$G$48<'Tabela Jogos'!$E$48),COUNT('Tabela Jogos'!$G$48))) -> 0 | G45: =SUM((('Tabela Jogos'!E44+'Tabela Jogos'!E46)+'Tabela Jogos'!G48)) -> 8 | H45: =SUM((('Tabela Jogos'!G44+'Tabela Jogos'!G46)+'Tabela Jogos'!E48)) -> 3 | I45: =SUM((G45-H45)) -> 5 | K45: =IF((B45>=B46),A45,A46) -> Holanda | L45: =VLOOKUP(K45,$A$45:$I$48,2,FALSE) -> 9 | N45: =IF((L45>=L47),K45,K47) -> Holanda | O45: =VLOOKUP(N45,$A$45:$I$48,2,FALSE) -> 9 | Q45: =IF((O45>=O48),N45,N48) -> Holanda | R45: =VLOOKUP(Q45,$A$45:$I$48,2,FALSE) -> 9 | S45: =VLOOKUP(Q45,$A$45:$I$48,9,FALSE) -> 5 | U45: =IF(AND((R45=R46),(S46>S45)),Q46,Q45) -> Holanda | V45: =VLOOKUP(U45,$A$45:$I$48,2,FALSE) -> 9 | W45: =VLOOKUP(U45,$A$45:$I$48,9,FALSE) -> 5 | X45: =IF(AND((V45=V47),(W47>W45)),U47,U45) -> Holanda | Y45: =VLOOKUP(X45,$A$45:$I$48,2,FALSE) -> 9 | Z45: =VLOOKUP(X45,$A$45:$I$48,9,FALSE) -> 5 | AB45: =IF(AND((Y45=Y48),(Z48>Z45)),X48,X45) -> Holanda | AC45: =VLOOKUP(AB45,$A$45:$I$48,2,FALSE) -> 9 | AD45: =VLOOKUP(AB45,$A$45:$I$48,9,FALSE) -> 5 | AE45: =VLOOKUP(AB45,$A$45:$I$48,7,FALSE) -> 8 | AF45: =IF(AND((AC45=AC46),(AD45=AD46),(AE46>AE45)),AB46,AB45) -> Holanda | AG45: =VLOOKUP(AF45,$A$45:$I$48,2,FALSE) -> 9 | AH45: =VLOOKUP(AF45,$A$45:$I$48,9,FALSE) -> 5 | AI45: =VLOOKUP(AF45,$A$45:$I$48,7,FALSE) -> 8 | AJ45: =IF(AND((AG45=AG47),(AH45=AH47),(AI47>AI45)),AF47,AF45) -> Holanda | AK45: =VLOOKUP(AJ45,$A$45:$I$48,2,FALSE) -> 9 | AL45: =VLOOKUP(AJ45,$A$45:$I$48,9,FALSE) -> 5 | AM45: =VLOOKUP(AJ45,$A$45:$I$48,7,FALSE) -> 8 | AN45: =IF(AND((AK45=AK48),(AL45=AL48),(AM48>AM45)),AJ48,AJ45) -> Holanda | AO45: =VLOOKUP(AN45,$A$45:$I$48,2,FALSE) -> 9 | AP45: =VLOOKUP(AN45,$A$45:$I$48,9,FALSE) -> 5 | AQ45: =VLOOKUP(AN45,$A$45:$I$48,7,FALSE) -> 8
A46: Japão | B46: =SUM((D46*3))+E46 -> 6 | C46: =COUNT('Tabela Jogos'!G44,'Tabela Jogos'!G47,'Tabela Jogos'!E49) -> 3 | D46: =SUM(IF(('Tabela Jogos'!$G$44>'Tabela Jogos'!$E$44),COUNT('Tabela Jogos'!$G$44)),IF(('Tabela Jogos'!$G$47>'Tabela Jogos'!$E$47),COUNT('Tabela Jogos'!$G$47)),IF(('Tabela Jogos'!$E$49>'Tabela Jogos'!$G$49),COUNT('Tabela Jogos'!$E$49))) -> 2 | E46: =SUM(IF(('Tabela Jogos'!$G$44='Tabela Jogos'!$E$44),COUNT('Tabela Jogos'!$G$44)),IF(('Tabela Jogos'!$G$47='Tabela Jogos'!$E$47),COUNT('Tabela Jogos'!$G$47)),IF(('Tabela Jogos'!$E$49='Tabela Jogos'!$G$49),COUNT('Tabela Jogos'!$E$49))) -> 0 | F46: =SUM(IF(('Tabela Jogos'!$G$44<'Tabela Jogos'!$E$44),COUNT('Tabela Jogos'!$G$44)),IF(('Tabela Jogos'!$G$47<'Tabela Jogos'!$E$47),COUNT('Tabela Jogos'!$G$47)),IF(('Tabela Jogos'!$E$49<'Tabela Jogos'!$G$49),COUNT('Tabela Jogos'!$E$49))) -> 1 | G46: =SUM((('Tabela Jogos'!G44+'Tabela Jogos'!G47)+'Tabela Jogos'!E49)) -> 5 | H46: =SUM((('Tabela Jogos'!E44+'Tabela Jogos'!E47)+'Tabela Jogos'!G49)) -> 5 | I46: =SUM((G46-H46)) -> 0 | K46: =IF((B46<=B45),A46,A45) -> Japão | L46: =VLOOKUP(K46,$A$45:$I$48,2,FALSE) -> 6 | N46: =IF((L46>=L48),K46,K48) -> Japão | O46: =VLOOKUP(N46,$A$45:$I$48,2,FALSE) -> 6 | Q46: =IF((O46>=O47),N46,N47) -> Japão | R46: =VLOOKUP(Q46,$A$45:$I$48,2,FALSE) -> 6 | S46: =VLOOKUP(Q46,$A$45:$I$48,9,FALSE) -> 0 | U46: =IF(AND((R45=R46),(S46>S45)),Q45,Q46) -> Japão | V46: =VLOOKUP(U46,$A$45:$I$48,2,FALSE) -> 6 | W46: =VLOOKUP(U46,$A$45:$I$48,9,FALSE) -> 0 | X46: =IF(AND((V46=V48),(W48>W46)),U48,U46) -> Japão | Y46: =VLOOKUP(X46,$A$45:$I$48,2,FALSE) -> 6 | Z46: =VLOOKUP(X46,$A$45:$I$48,9,FALSE) -> 0 | AB46: =IF(AND((Y46=Y47),(Z47>Z46)),X47,X46) -> Japão | AC46: =VLOOKUP(AB46,$A$45:$I$48,2,FALSE) -> 6 | AD46: =VLOOKUP(AB46,$A$45:$I$48,9,FALSE) -> 0 | AE46: =VLOOKUP(AB46,$A$45:$I$48,7,FALSE) -> 5 | AF46: =IF(AND((AC46=AC45),(AD46=AD45),(AE46>AE45)),AB45,AB46) -> Japão | AG46: =VLOOKUP(AF46,$A$45:$I$48,2,FALSE) -> 6 | AH46: =VLOOKUP(AF46,$A$45:$I$48,9,FALSE) -> 0 | AI46: =VLOOKUP(AF46,$A$45:$I$48,7,FALSE) -> 5 | AJ46: =IF(AND((AG46=AG48),(AH46=AH48),(AI48>AI46)),AF48,AF46) -> Japão | AK46: =VLOOKUP(AJ46,$A$45:$I$48,2,FALSE) -> 6 | AL46: =VLOOKUP(AJ46,$A$45:$I$48,9,FALSE) -> 0 | AM46: =VLOOKUP(AJ46,$A$45:$I$48,7,FALSE) -> 5 | AN46: =IF(AND((AK46=AK47),(AL46=AL47),(AM47>AM46)),AJ47,AJ46) -> Japão | AO46: =VLOOKUP(AN46,$A$45:$I$48,2,FALSE) -> 6 | AP46: =VLOOKUP(AN46,$A$45:$I$48,9,FALSE) -> 0 | AQ46: =VLOOKUP(AN46,$A$45:$I$48,7,FALSE) -> 5
